Workbook
Name UPDATE: 'Data Sheet'!$E$1

Sheet Index
B2: ='Data Sheet'!$B$1 -> TATA CONSUMER PRODUCTS LTD
B4: Equity Research & Valuation Model
B6: Prepared by : | C6: Ashish Jha | L6: Metric | N6: Value
C7: NIT Surat
L8: CMP | N8: ='Investment Summary'!C8 -> ₹1,196.00
B9: Company : | C9: =B2 -> TATA CONSUMER PRODUCTS LTD
B10: Sector : | C10: FMCG | L10: DCF Value | N10: ='Investment Summary'!C10 -> ₹98.86
B11: Currency : | C11: INR ( ₹ )
B12: Valuation Date : | C12: =TODAY() -> 46193 | L12: Relative Valuation | N12: ='Investment Summary'!C12 -> ₹781 - ₹1,476
L14: View | N14: Fairly Valued
A15: # | B15: Navigation
L16: Recommendation | N16: HOLD
C17: Investment Summary
C19: Data Sheet
C21: Historical Financial Statement
C23: Ratio Analysis
C25: Forecasting
C27: WACC
C29: Beta Regression
C31: Return on Markets
C33: Common Size Statement
C35: Raw Financial Statement
C37: Intrinsic Growth Rate
C39: DCF Valuation
... C47: Monte Carlo Simulation
A49: # | B49: Model Flow
C51: Stage | E51: Purpose
C53: Data collection | D53: Gather historial financial and market data.
C56: Ratio Analysis | D56: Analyze trends, profitability & efficiency.
C59: Forecasting | D59: Project future operating performance.
C62: WACC | D62: Estimate cost of capital.
C65: DCF & Relative Valuation | D65: Determine intrinsic & relative value.
C68: Investment Conclusion | D68: Form investment view.
B70: Source: Screener, Yahoo Finance, Company Annual Reports, Valuation School

Sheet Investment Summary
B2: ='Data Sheet'!$B$1 -> TATA CONSUMER PRODUCTS LTD
B4: Equity Research & Valuation Model
A6: # | B6: Company Overiew
B8: CMP | C8: ="₹"&TEXT('Comps Val'!D8,"#,##0.00") -> ₹1,196.00
B10: DCF Value | C10: ="₹"&TEXT(DCF!D37, "#,##0.00") -> ₹98.86
B12: Relative Comps Value | C12: ="₹"&TEXT(MIN('Comps Val'!O32:Q32),"#,##0")&" - ₹"&TEXT(MAX('Comps Val'!O32:Q32),"#,##0") -> ₹781 - ₹1,476
A14: # | B14: DCF Valuation Summary
A22: # | B22: Relative Valuation Summary
A30: # | B30: Key Investment Positives
B32: 1. Strong portfolio of established consumer brands across beverages and food categories.
B33: 2. Backed by the Tata Group, providing strong brand equity and governance standards.
B34: 3. Consistent revenue growth and healthy operating margins over the historical period.
B35: 4. Long-term growth opportunities from premiumization and expansion of food products.
A37: # | B37: Key Investment Risks
B39: 1. Premium valuation relative to several FMCG peers on earnings-based multiples.
B40: 2. Raw material inflation may put pressure on operating margins.
B41: 3. DCF valuation remains sensitive to assumptions regarding reinvestment rates and long-term growth.
B42: 4. Intensifying competition from both established FMCG players and emerging brands.
A44: # | B44: Final Investment View
A53: # | B53: Football Field Analysis
A74: # | B74: Investment View
B76: Recommendation : | C76: HOLD
B78: CMP | C78: =Index!N8 -> ₹1,196.00
B80: Relative Valuation Range | C80: =Index!N12 -> ₹781 - ₹1,476
B82: Investment View | C82: =Index!N14 -> Fairly Valued

Sheet Profit & Loss
A1: ='Data Sheet'!B1 -> TATA CONSUMER PRODUCTS LTD | H1: =UPDATE | M1: SCREENER.IN
A3: Narration | B3: ='Data Sheet'!B16 -> 42460 | C3: ='Data Sheet'!C16 -> 42825 | D3: ='Data Sheet'!D16 -> 43190 | E3: ='Data Sheet'!E16 -> 43555 | F3: ='Data Sheet'!F16 -> 43921 | G3: ='Data Sheet'!G16 -> 44286 | H3: ='Data Sheet'!H16 -> 44651 | I3: ='Data Sheet'!I16 -> 45016 | ... K3: ='Data Sheet'!K16 -> 45747 | L3: Trailing | M3: Best Case | N3: Worst Case
A4: Sales | B4: ='Data Sheet'!B17 -> 6636.54 | C4: ='Data Sheet'!C17 -> 6779.55 | D4: ='Data Sheet'!D17 -> 6815.35 | E4: ='Data Sheet'!E17 -> 7251.5 | F4: ='Data Sheet'!F17 -> 9637.42 | G4: ='Data Sheet'!G17 -> 11602.03 | H4: ='Data Sheet'!H17 -> 12425.37 | I4: ='Data Sheet'!I17 -> 13783.16 | ... K4: ='Data Sheet'!K17 -> 17618.3 | L4: =SUM(Quarters!H4:K4) -> 19465.03 | M4: =$K4+M23*K4 -> 20413.492 | N4: =$K4+N23*L4 -> 19848.72
A5: Expenses | B5: =SUM('Data Sheet'!B18,'Data Sheet'!B20:B24, -1*'Data Sheet'!B19) -> 6270.63 | C5: =SUM('Data Sheet'!C18,'Data Sheet'!C20:C24, -1*'Data Sheet'!C19) -> 5988.42 | D5: =SUM('Data Sheet'!D18,'Data Sheet'!D20:D24, -1*'Data Sheet'!D19) -> 5976.44 | E5: =SUM('Data Sheet'!E18,'Data Sheet'!E20:E24, -1*'Data Sheet'!E19) -> 6465.59 | F5: =SUM('Data Sheet'!F18,'Data Sheet'!F20:F24, -1*'Data Sheet'!F19) -> 8345.27 | G5: =SUM('Data Sheet'!G18,'Data Sheet'!G20:G24, -1*'Data Sheet'!G19) -> 10058.27 | H5: =SUM('Data Sheet'!H18,'Data Sheet'!H20:H24, -1*'Data Sheet'!H19) -> 10706.59 | I5: =SUM('Data Sheet'!I18,'Data Sheet'!I20:I24, -1*'Data Sheet'!I19) -> 11926.69 | ... K5: =SUM('Data Sheet'!K18,'Data Sheet'!K20:K24, -1*'Data Sheet'!K19) -> 15138.95 | L5: =SUM(Quarters!H5:K5) -> 12453.36 | M5: =M4-M6 -> 17514.039 | N5: =N4-N6 -> 17277.908
A6: Operating Profit | B6: =B4-B5 -> 365.91 | C6: =C4-C5 -> 791.13 | D6: =D4-D5 -> 838.91 | E6: =E4-E5 -> 785.91 | F6: =F4-F5 -> 1292.15 | G6: =G4-G5 -> 1543.76 | H6: =H4-H5 -> 1718.78 | I6: =I4-I5 -> 1856.47 | ... K6: =K4-K5 -> 2479.35 | L6: =SUM(Quarters!H6:K6) -> 2620.34 | M6: =M4*M24 -> 2899.4525 | N6: =N4*N24 -> 2570.8124
A7: Other Income | B7: ='Data Sheet'!B25 -> 37.54 | C7: ='Data Sheet'!C25 -> 88.4 | D7: ='Data Sheet'!D25 -> 73.02 | E7: ='Data Sheet'!E25 -> 123.84 | F7: ='Data Sheet'!F25 -> -163.2 | G7: ='Data Sheet'!G25 -> 90.73 | H7: ='Data Sheet'!H25 -> 88 | I7: ='Data Sheet'!I25 -> 328.33 | ... K7: ='Data Sheet'!K25 -> 188.14 | L7: =SUM(Quarters!H7:K7) -> 191.16 | M7: 0 | N7: 0
A8: Depreciation | B8: ='Data Sheet'!B26 -> 116.79 | C8: ='Data Sheet'!C26 -> 126.04 | D8: ='Data Sheet'!D26 -> 116.04 | E8: ='Data Sheet'!E26 -> 122.57 | F8: ='Data Sheet'!F26 -> 241.71 | G8: ='Data Sheet'!G26 -> 254.74 | H8: ='Data Sheet'!H26 -> 278.01 | I8: ='Data Sheet'!I26 -> 304.08 | ... K8: ='Data Sheet'!K26 -> 600.74 | L8: =SUM(Quarters!H8:K8) -> 614.59 | M8: =+$L8 -> 614.59 | N8: =+$L8 -> 614.59
A9: Interest | B9: ='Data Sheet'!B27 -> 116.9 | C9: ='Data Sheet'!C27 -> 91.53 | D9: ='Data Sheet'!D27 -> 42.76 | E9: ='Data Sheet'!E27 -> 52.47 | F9: ='Data Sheet'!F27 -> 77.86 | G9: ='Data Sheet'!G27 -> 68.69 | H9: ='Data Sheet'!H27 -> 72.78 | I9: ='Data Sheet'!I27 -> 87.16 | ... K9: ='Data Sheet'!K27 -> 290.2 | L9: =SUM(Quarters!H9:K9) -> 138.6 | M9: =+$L9 -> 138.6 | N9: =+$L9 -> 138.6
A10: Profit before tax | B10: ='Data Sheet'!B28 -> 169.76 | C10: ='Data Sheet'!C28 -> 661.96 | D10: ='Data Sheet'!D28 -> 753.13 | E10: ='Data Sheet'!E28 -> 734.71 | F10: ='Data Sheet'!F28 -> 809.38 | G10: ='Data Sheet'!G28 -> 1311.06 | H10: ='Data Sheet'!H28 -> 1455.99 | I10: ='Data Sheet'!I28 -> 1793.56 | ... K10: ='Data Sheet'!K28 -> 1776.55 | L10: =SUM(Quarters!H10:K10) -> 2058.31 | M10: =M6+M7-SUM(M8:M9) -> 2146.2625 | N10: =N6+N7-SUM(N8:N9) -> 1817.6224
A11: Tax | B11: ='Data Sheet'!B29 -> 200.01 | C11: ='Data Sheet'!C29 -> 198.31 | D11: ='Data Sheet'!D29 -> 185.87 | E11: ='Data Sheet'!E29 -> 260.88 | F11: ='Data Sheet'!F29 -> 274.19 | G11: ='Data Sheet'!G29 -> 317.27 | H11: ='Data Sheet'!H29 -> 377.04 | I11: ='Data Sheet'!I29 -> 447.04 | ... K11: ='Data Sheet'!K29 -> 396.24 | L11: =SUM(Quarters!H11:K11) -> 504.96 | M11: =IF($L10>0,$L11/$L10,0) -> 0.24532748 | N11: =IF($L10>0,$L11/$L10,0) -> 0.24532748
A12: Net profit | B12: ='Data Sheet'!B30 -> -5.52 | C12: ='Data Sheet'!C30 -> 389.44 | D12: ='Data Sheet'!D30 -> 495.56 | E12: ='Data Sheet'!E30 -> 408.19 | F12: ='Data Sheet'!F30 -> 459.76 | G12: ='Data Sheet'!G30 -> 856.69 | H12: ='Data Sheet'!H30 -> 935.78 | I12: ='Data Sheet'!I30 -> 1203.77 | ... K12: ='Data Sheet'!K30 -> 1278.47 | L12: =SUM(Quarters!H12:K12) -> 1468.07 | M12: =M10-M11*M10 -> 1619.7254 | N12: =N10-N11*N10 -> 1371.7097
A13: EPS | B13: =IF('Data Sheet'!B93>0,B12/'Data Sheet'!B93,0) -> -0.084223375 | C13: =IF('Data Sheet'!C93>0,C12/'Data Sheet'!C93,0) -> 5.9420201 | D13: =IF('Data Sheet'!D93>0,D12/'Data Sheet'!D93,0) -> 7.561184 | E13: =IF('Data Sheet'!E93>0,E12/'Data Sheet'!E93,0) -> 6.228105 | F13: =IF('Data Sheet'!F93>0,F12/'Data Sheet'!F93,0) -> 4.8041797 | G13: =IF('Data Sheet'!G93>0,G12/'Data Sheet'!G93,0) -> 8.9518286 | H13: =IF('Data Sheet'!H93>0,H12/'Data Sheet'!H93,0) -> 9.7782654 | I13: =IF('Data Sheet'!I93>0,I12/'Data Sheet'!I93,0) -> 12.47818 | ... K13: =IF('Data Sheet'!K93>0,K12/'Data Sheet'!K93,0) -> 12.920364 | L13: =IF('Data Sheet'!$B6>0,'Profit & Loss'!L12/'Data Sheet'!$B6,0) -> 14.886717 | M13: =IF('Data Sheet'!$B6>0,'Profit & Loss'!M12/'Data Sheet'!$B6,0) -> 16.424553 | N13: =IF('Data Sheet'!$B6>0,'Profit & Loss'!N12/'Data Sheet'!$B6,0) -> 13.909592
A14: Price to earning | B14: =IF(B15>0,B15/B13,"") -> -1421.933 | C14: =IF(C15>0,C15/C13,"") -> 25.025159 | D14: =IF(D15>0,D15/D13,"") -> 33.800262 | E14: =IF(E15>0,E15/E13,"") -> 32.345312 | F14: =IF(F15>0,F15/F13,"") -> 60.62013 | G14: =IF(G15>0,G15/G13,"") -> 70.495094 | H14: =IF(H15>0,H15/H13,"") -> 78.52722 | I14: =IF(I15>0,I15/I13,"") -> 56.109947 | ... K14: =IF(K15>0,K15/K13,"") -> 77.544256 | L14: =IF(L13>0,L15/L13,0) -> 76.524594 | M14: =M25 -> 76.524594 | N14: =N25 -> 60.412796
A15: Price | B15: ='Data Sheet'!B90 -> 119.76 | C15: ='Data Sheet'!C90 -> 148.7 | D15: ='Data Sheet'!D90 -> 255.57 | E15: ='Data Sheet'!E90 -> 201.45 | F15: ='Data Sheet'!F90 -> 291.23 | G15: ='Data Sheet'!G90 -> 631.06 | H15: ='Data Sheet'!H90 -> 767.86 | I15: ='Data Sheet'!I90 -> 700.15 | ... K15: ='Data Sheet'!K90 -> 1001.9 | L15: ='Data Sheet'!B8 -> 1139.2 | M15: =M13*M14 -> 1256.8823 | N15: =N13*N14 -> 840.31732
A17: RATIOS:
A18: Dividend Payout | B18: =IF('Data Sheet'!B30>0, 'Data Sheet'!B31/'Data Sheet'!B30, 0) -> 0 | C18: =IF('Data Sheet'!C30>0, 'Data Sheet'!C31/'Data Sheet'!C30, 0) -> 0.38082888 | D18: =IF('Data Sheet'!D30>0, 'Data Sheet'!D31/'Data Sheet'!D30, 0) -> 0.29927758 | E18: =IF('Data Sheet'!E30>0, 'Data Sheet'!E31/'Data Sheet'!E30, 0) -> 0.38653568 | F18: =IF('Data Sheet'!F30>0, 'Data Sheet'!F31/'Data Sheet'!F30, 0) -> 0.54121716 | G18: =IF('Data Sheet'!G30>0, 'Data Sheet'!G31/'Data Sheet'!G30, 0) -> 0.43568852 | H18: =IF('Data Sheet'!H30>0, 'Data Sheet'!H31/'Data Sheet'!H30, 0) -> 0.59583449 | I18: =IF('Data Sheet'!I30>0, 'Data Sheet'!I31/'Data Sheet'!I30, 0) -> 0.65211793 | ... K18: =IF('Data Sheet'!K30>0, 'Data Sheet'!K31/'Data Sheet'!K30, 0) -> 0.63852887
A19: OPM | B19: =IF(B6>0,B6/B4,0) -> 0.055135658 | C19: =IF(C6>0,C6/C4,0) -> 0.11669359 | D19: =IF(D6>0,D6/D4,0) -> 0.12309126 | E19: =IF(E6>0,E6/E4,0) -> 0.10837896 | F19: =IF(F6>0,F6/F4,0) -> 0.13407634 | G19: =IF(G6>0,G6/G4,0) -> 0.13305947 | H19: =IF(H6>0,H6/H4,0) -> 0.13832828 | I19: =IF(I6>0,I6/I4,0) -> 0.13469117 | ... L19: =IF(L6>0,L6/L4,0) -> 0.13461782
G22: TRENDS: | H22: 10 YEARS | I22: 7 YEARS | J22: 5 YEARS | K22: 3 YEARS | L22: RECENT | M22: BEST | N22: WORST
G23: Sales Growth | H23: =IF(B4=0,"",POWER($K4/B4,1/9)-1) -> 0.11458601 | I23: =IF(D4=0,"",POWER($K4/D4,1/7)-1) -> 0.14531545 | J23: =IF(F4=0,"",POWER($K4/F4,1/5)-1) -> 0.12823779 | K23: =IF(H4=0,"",POWER($K4/H4, 1/3)-1) -> 0.12344433 | L23: =IF(ISERROR(MAX(IF(J4=0,"",(K4-J4)/J4),IF(K4=0,"",(L4-K4)/K4))),"",MAX(IF(J4=0,"",(K4-J4)/J4),IF(K4=0,"",(L4-K4)/K4))) -> 0.15865276 | M23: =MAX(K23:L23) -> 0.15865276 | N23: =MIN(H23:L23) -> 0.11458601
G24: OPM | H24: =IF(SUM(B4:$K$4)=0,"",SUMPRODUCT(B19:$K$19,B4:$K$4)/SUM(B4:$K$4)) -> 0.12952031 | I24: =IF(SUM(E4:$K$4)=0,"",SUMPRODUCT(E19:$K$19,E4:$K$4)/SUM(E4:$K$4)) -> 0.13665475 | J24: =IF(SUM(G4:$K$4)=0,"",SUMPRODUCT(G19:$K$19,G4:$K$4)/SUM(G4:$K$4)) -> 0.1399094 | K24: =IF(SUM(I4:$K$4)=0, "", SUMPRODUCT(I19:$K$19,I4:$K$4)/SUM(I4:$K$4)) -> 0.14203609 | L24: =L19 -> 0.13461782 | M24: =MAX(K24:L24) -> 0.14203609 | N24: =MIN(H24:L24) -> 0.12952031
G25: Price to Earning | H25: =IF(ISERROR(AVERAGEIF(B14:$L14,">0")),"",AVERAGEIF(B14:$L14,">0")) -> 60.412796 | I25: =IF(ISERROR(AVERAGEIF(E14:$L14,">0")),"",AVERAGEIF(E14:$L14,">0")) -> 68.162818 | J25: =IF(ISERROR(AVERAGEIF(G14:$L14,">0")),"",AVERAGEIF(G14:$L14,">0")) -> 75.389517 | K25: =IF(ISERROR(AVERAGEIF(I14:$L14,">0")),"",AVERAGEIF(I14:$L14,">0")) -> 75.828696 | L25: =L14 -> 76.524594 | M25: =MAX(K25:L25) -> 76.524594 | N25: =MIN(H25:L25) -> 60.412796

Sheet Quarters
A1: ='Profit & Loss'!A1 -> TATA CONSUMER PRODUCTS LTD | E1: =UPDATE | J1: SCREENER.IN
A3: Narration | B3: ='Data Sheet'!B41 -> 45199 | C3: ='Data Sheet'!C41 -> 45291 | D3: ='Data Sheet'!D41 -> 45382 | E3: ='Data Sheet'!E41 -> 45473 | F3: ='Data Sheet'!F41 -> 45565 | G3: ='Data Sheet'!G41 -> 45657 | H3: ='Data Sheet'!H41 -> 45747 | I3: ='Data Sheet'!I41 -> 45838 | ... K3: ='Data Sheet'!K41 -> 46022
A4: Sales | B4: ='Data Sheet'!B42 -> 3733.78 | C4: ='Data Sheet'!C42 -> 3803.92 | D4: ='Data Sheet'!D42 -> 3926.94 | E4: ='Data Sheet'!E42 -> 4352.07 | F4: ='Data Sheet'!F42 -> 4214.45 | G4: ='Data Sheet'!G42 -> 4443.56 | H4: ='Data Sheet'!H42 -> 4608.22 | I4: ='Data Sheet'!I42 -> 4778.91 | ... K4: ='Data Sheet'!K42 -> 5112
A5: Expenses | B5: ='Data Sheet'!B43 -> 3196.69 | C5: ='Data Sheet'!C43 -> 3231.54 | D5: ='Data Sheet'!D43 -> 3297.34 | E5: ='Data Sheet'!E43 -> 3684.69 | F5: ='Data Sheet'!F43 -> 3588.16 | G5: ='Data Sheet'!G43 -> 3878.83 | H5: ='Data Sheet'!H43 -> 3987.27 | I5: ='Data Sheet'!I43 -> 4171.97 | J5: ='Data Sheet'!J43 -> 4294.12
A6: Operating Profit | B6: ='Data Sheet'!B50 -> 537.09 | C6: ='Data Sheet'!C50 -> 572.38 | D6: ='Data Sheet'!D50 -> 629.6 | E6: ='Data Sheet'!E50 -> 667.38 | F6: ='Data Sheet'!F50 -> 626.29 | G6: ='Data Sheet'!G50 -> 564.73 | H6: ='Data Sheet'!H50 -> 620.95 | I6: ='Data Sheet'!I50 -> 606.94 | ... K6: ='Data Sheet'!K50 -> 720.67
A7: Other Income | B7: ='Data Sheet'!B44 -> 75.28 | C7: ='Data Sheet'!C44 -> -31.94 | D7: ='Data Sheet'!D44 -> -177.35 | E7: ='Data Sheet'!E44 -> 22.07 | F7: ='Data Sheet'!F44 -> 18.8 | G7: ='Data Sheet'!G44 -> 45.44 | H7: ='Data Sheet'!H44 -> 101.83 | I7: ='Data Sheet'!I44 -> 41.17 | ... K7: ='Data Sheet'!K44 -> 10.15
A8: Depreciation | B8: ='Data Sheet'!B45 -> 93.93 | C8: ='Data Sheet'!C45 -> 85.51 | D8: ='Data Sheet'!D45 -> 115.76 | E8: ='Data Sheet'!E45 -> 148 | F8: ='Data Sheet'!F45 -> 149.33 | G8: ='Data Sheet'!G45 -> 150.32 | H8: ='Data Sheet'!H45 -> 153.09 | I8: ='Data Sheet'!I45 -> 148.93 | ... K8: ='Data Sheet'!K45 -> 159.29
A9: Interest | B9: ='Data Sheet'!B46 -> 27.56 | C9: ='Data Sheet'!C46 -> 33.19 | D9: ='Data Sheet'!D46 -> 42.83 | E9: ='Data Sheet'!E46 -> 93.6 | F9: ='Data Sheet'!F46 -> 98.69 | G9: ='Data Sheet'!G46 -> 57.92 | H9: ='Data Sheet'!H46 -> 39.99 | I9: ='Data Sheet'!I46 -> 33.76 | ... K9: ='Data Sheet'!K46 -> 31.62
A10: Profit before tax | B10: ='Data Sheet'!B47 -> 490.88 | C10: ='Data Sheet'!C47 -> 421.74 | D10: ='Data Sheet'!D47 -> 293.66 | E10: ='Data Sheet'!E47 -> 447.85 | F10: ='Data Sheet'!F47 -> 397.07 | G10: ='Data Sheet'!G47 -> 401.93 | H10: ='Data Sheet'!H47 -> 529.7 | I10: ='Data Sheet'!I47 -> 465.42 | ... K10: ='Data Sheet'!K47 -> 539.91
A11: Tax | B11: ='Data Sheet'!B48 -> 131.7 | C11: ='Data Sheet'!C48 -> 106.21 | D11: ='Data Sheet'!D48 -> 25.95 | E11: ='Data Sheet'!E48 -> 133.7 | F11: ='Data Sheet'!F48 -> 37.73 | G11: ='Data Sheet'!G48 -> 102.18 | H11: ='Data Sheet'!H48 -> 122.63 | I11: ='Data Sheet'!I48 -> 118.98 | ... K11: ='Data Sheet'!K48 -> 137.12
A12: Net profit | B12: ='Data Sheet'!B49 -> 338.24 | C12: ='Data Sheet'!C49 -> 278.87 | D12: ='Data Sheet'!D49 -> 216.63 | E12: ='Data Sheet'!E49 -> 290.32 | F12: ='Data Sheet'!F49 -> 364.42 | G12: ='Data Sheet'!G49 -> 278.88 | H12: ='Data Sheet'!H49 -> 344.85 | I12: ='Data Sheet'!I49 -> 334.15 | ... K12: ='Data Sheet'!K49 -> 384.61
A14: OPM | B14: =IF(B4>0,B6/B4,"") -> 0.14384618 | C14: =IF(C4>0,C6/C4,"") -> 0.15047109 | D14: =IF(D4>0,D6/D4,"") -> 0.1603284 | E14: =IF(E4>0,E6/E4,"") -> 0.15334772 | F14: =IF(F4>0,F6/F4,"") -> 0.14860539 | G14: =IF(G4>0,G6/G4,"") -> 0.12708954 | H14: =IF(H4>0,H6/H4,"") -> 0.13474834 | I14: =IF(I4>0,I6/I4,"") -> 0.12700386 | ... K14: =IF(K4>0,K6/K4,"") -> 0.14097613

Sheet Balance Sheet
A1: ='Profit & Loss'!A1 -> TATA CONSUMER PRODUCTS LTD | E1: =UPDATE | J1: SCREENER.IN
A3: Narration | B3: ='Data Sheet'!B56 -> 42460 | C3: ='Data Sheet'!C56 -> 42825 | D3: ='Data Sheet'!D56 -> 43190 | E3: ='Data Sheet'!E56 -> 43555 | F3: ='Data Sheet'!F56 -> 43921 | G3: ='Data Sheet'!G56 -> 44286 | H3: ='Data Sheet'!H56 -> 44651 | I3: ='Data Sheet'!I56 -> 45016 | ... K3: ='Data Sheet'!K56 -> 45747
A4: Equity Share Capital | B4: ='Data Sheet'!B57 -> 63.11 | C4: ='Data Sheet'!C57 -> 63.11 | D4: ='Data Sheet'!D57 -> 63.11 | E4: ='Data Sheet'!E57 -> 63.11 | F4: ='Data Sheet'!F57 -> 92.16 | G4: ='Data Sheet'!G57 -> 92.16 | H4: ='Data Sheet'!H57 -> 92.16 | I4: ='Data Sheet'!I57 -> 92.9 | ... K4: ='Data Sheet'!K57 -> 98.95
A5: Reserves | B5: ='Data Sheet'!B58 -> 6184.06 | C5: ='Data Sheet'!C58 -> 6202.39 | D5: ='Data Sheet'!D58 -> 6968.49 | E5: ='Data Sheet'!E58 -> 7268.58 | F5: ='Data Sheet'!F58 -> 13722.7 | G5: ='Data Sheet'!G58 -> 14442.35 | H5: ='Data Sheet'!H58 -> 15049.78 | I5: ='Data Sheet'!I58 -> 16183.81 | ... K5: ='Data Sheet'!K58 -> 19902.13
A6: Borrowings | B6: ='Data Sheet'!B59 -> 1354.05 | C6: ='Data Sheet'!C59 -> 786.56 | D6: ='Data Sheet'!D59 -> 1067.58 | E6: ='Data Sheet'!E59 -> 1141.1 | F6: ='Data Sheet'!F59 -> 1586.32 | G6: ='Data Sheet'!G59 -> 1633.55 | H6: ='Data Sheet'!H59 -> 1412.01 | I6: ='Data Sheet'!I59 -> 1600.04 | ... K6: ='Data Sheet'!K59 -> 2392.68
A7: Other Liabilities | B7: ='Data Sheet'!B60 -> 2293.54 | C7: ='Data Sheet'!C60 -> 2499.35 | D7: ='Data Sheet'!D60 -> 2361.58 | E7: ='Data Sheet'!E60 -> 2407.89 | F7: ='Data Sheet'!F60 -> 3071.86 | G7: ='Data Sheet'!G60 -> 4049.76 | H7: ='Data Sheet'!H60 -> 4520.92 | I7: ='Data Sheet'!I60 -> 4885.74 | ... K7: ='Data Sheet'!K60 -> 9436.86
A8: Total | B8: ='Data Sheet'!B61 -> 9894.76 | C8: ='Data Sheet'!C61 -> 9551.41 | D8: ='Data Sheet'!D61 -> 10460.76 | E8: ='Data Sheet'!E61 -> 10880.68 | F8: ='Data Sheet'!F61 -> 18473.04 | G8: ='Data Sheet'!G61 -> 20217.82 | H8: ='Data Sheet'!H61 -> 21074.87 | I8: ='Data Sheet'!I61 -> 22762.49 | ... K8: ='Data Sheet'!K61 -> 31830.62
A10: Net Block | B10: ='Data Sheet'!B62 -> 4661.8 | C10: ='Data Sheet'!C62 -> 4572.59 | D10: ='Data Sheet'!D62 -> 4798.18 | E10: ='Data Sheet'!E62 -> 4913.31 | F10: ='Data Sheet'!F62 -> 11656.04 | G10: ='Data Sheet'!G62 -> 12023.13 | H10: ='Data Sheet'!H62 -> 12599.35 | I10: ='Data Sheet'!I62 -> 13070.04 | ... K10: ='Data Sheet'!K62 -> 21476.84
A11: Capital Work in Progress | B11: ='Data Sheet'!B63 -> 39.42 | C11: ='Data Sheet'!C63 -> 63.19 | D11: ='Data Sheet'!D63 -> 135.16 | E11: ='Data Sheet'!E63 -> 424.41 | F11: ='Data Sheet'!F63 -> 95.35 | G11: ='Data Sheet'!G63 -> 112.85 | H11: ='Data Sheet'!H63 -> 246.97 | I11: ='Data Sheet'!I63 -> 294.9 | ... K11: ='Data Sheet'!K63 -> 218.1
A12: Investments | B12: ='Data Sheet'!B64 -> 1365.94 | C12: ='Data Sheet'!C64 -> 1451.04 | D12: ='Data Sheet'!D64 -> 1161.33 | E12: ='Data Sheet'!E64 -> 1187.66 | F12: ='Data Sheet'!F64 -> 1322.85 | G12: ='Data Sheet'!G64 -> 805.89 | H12: ='Data Sheet'!H64 -> 797.28 | I12: ='Data Sheet'!I64 -> 1432.97 | ... K12: ='Data Sheet'!K64 -> 968.67
A13: Other Assets | B13: ='Data Sheet'!B65 -> 3827.6 | C13: ='Data Sheet'!C65 -> 3464.59 | D13: ='Data Sheet'!D65 -> 4366.09 | E13: ='Data Sheet'!E65 -> 4355.3 | F13: ='Data Sheet'!F65 -> 5398.8 | G13: ='Data Sheet'!G65 -> 7275.95 | H13: ='Data Sheet'!H65 -> 7431.27 | I13: ='Data Sheet'!I65 -> 7964.58 | ... K13: ='Data Sheet'!K65 -> 9167.01
A14: Total | B14: ='Data Sheet'!B66 -> 9894.76 | C14: ='Data Sheet'!C66 -> 9551.41 | D14: ='Data Sheet'!D66 -> 10460.76 | E14: ='Data Sheet'!E66 -> 10880.68 | F14: ='Data Sheet'!F66 -> 18473.04 | G14: ='Data Sheet'!G66 -> 20217.82 | H14: ='Data Sheet'!H66 -> 21074.87 | I14: ='Data Sheet'!I66 -> 22762.49 | ... K14: ='Data Sheet'!K66 -> 31830.62
A16: Working Capital | B16: =B13-B7 -> 1534.06 | C16: =C13-C7 -> 965.24 | D16: =D13-D7 -> 2004.51 | E16: =E13-E7 -> 1947.41 | F16: =F13-F7 -> 2326.94 | G16: =G13-G7 -> 3226.19 | H16: =H13-H7 -> 2910.35 | I16: =I13-I7 -> 3078.84 | ... K16: =K13-K7 -> -269.85
A17: Debtors | B17: ='Data Sheet'!B67 -> 592.43 | C17: ='Data Sheet'!C67 -> 592.45 | D17: ='Data Sheet'!D67 -> 648.28 | E17: ='Data Sheet'!E67 -> 680.55 | F17: ='Data Sheet'!F67 -> 922.41 | G17: ='Data Sheet'!G67 -> 761.32 | H17: ='Data Sheet'!H67 -> 835.15 | I17: ='Data Sheet'!I67 -> 798.33 | ... K17: ='Data Sheet'!K67 -> 869.79
A18: Inventory | B18: ='Data Sheet'!B68 -> 1629.01 | C18: ='Data Sheet'!C68 -> 1452.96 | D18: ='Data Sheet'!D68 -> 1448.31 | E18: ='Data Sheet'!E68 -> 1608.54 | F18: ='Data Sheet'!F68 -> 1712.03 | G18: ='Data Sheet'!G68 -> 2249.16 | H18: ='Data Sheet'!H68 -> 2266.51 | I18: ='Data Sheet'!I68 -> 2701.67 | ... K18: ='Data Sheet'!K68 -> 3599.91
A20: Debtor Days | B20: =IF('Profit & Loss'!B4>0,'Balance Sheet'!B17/('Profit & Loss'!B4/365),0) -> 32.582784 | C20: =IF('Profit & Loss'!C4>0,'Balance Sheet'!C17/('Profit & Loss'!C4/365),0) -> 31.896549 | D20: =IF('Profit & Loss'!D4>0,'Balance Sheet'!D17/('Profit & Loss'!D4/365),0) -> 34.719009 | E20: =IF('Profit & Loss'!E4>0,'Balance Sheet'!E17/('Profit & Loss'!E4/365),0) -> 34.255085 | F20: =IF('Profit & Loss'!F4>0,'Balance Sheet'!F17/('Profit & Loss'!F4/365),0) -> 34.934625 | G20: =IF('Profit & Loss'!G4>0,'Balance Sheet'!G17/('Profit & Loss'!G4/365),0) -> 23.951136 | H20: =IF('Profit & Loss'!H4>0,'Balance Sheet'!H17/('Profit & Loss'!H4/365),0) -> 24.532851 | I20: =IF('Profit & Loss'!I4>0,'Balance Sheet'!I17/('Profit & Loss'!I4/365),0) -> 21.141048 | ... K20: =IF('Profit & Loss'!K4>0,'Balance Sheet'!K17/('Profit & Loss'!K4/365),0) -> 18.019522
A21: Inventory Turnover | B21: =IF('Balance Sheet'!B18>0,'Profit & Loss'!B4/'Balance Sheet'!B18,0) -> 4.0739713 | C21: =IF('Balance Sheet'!C18>0,'Profit & Loss'!C4/'Balance Sheet'!C18,0) -> 4.6660266 | D21: =IF('Balance Sheet'!D18>0,'Profit & Loss'!D4/'Balance Sheet'!D18,0) -> 4.705726 | E21: =IF('Balance Sheet'!E18>0,'Profit & Loss'!E4/'Balance Sheet'!E18,0) -> 4.5081254 | F21: =IF('Balance Sheet'!F18>0,'Profit & Loss'!F4/'Balance Sheet'!F18,0) -> 5.6292355 | G21: =IF('Balance Sheet'!G18>0,'Profit & Loss'!G4/'Balance Sheet'!G18,0) -> 5.1583836 | H21: =IF('Balance Sheet'!H18>0,'Profit & Loss'!H4/'Balance Sheet'!H18,0) -> 5.4821598 | I21: =IF('Balance Sheet'!I18>0,'Profit & Loss'!I4/'Balance Sheet'!I18,0) -> 5.1017186 | ... K21: =IF('Balance Sheet'!K18>0,'Profit & Loss'!K4/'Balance Sheet'!K18,0) -> 4.8940946
A23: Return on Equity | B23: =IF(SUM('Balance Sheet'!B4:B5)>0,'Profit & Loss'!B12/SUM('Balance Sheet'!B4:B5),"") -> -0.00088360009 | C23: =IF(SUM('Balance Sheet'!C4:C5)>0,'Profit & Loss'!C12/SUM('Balance Sheet'!C4:C5),"") -> 0.062156252 | D23: =IF(SUM('Balance Sheet'!D4:D5)>0,'Profit & Loss'!D12/SUM('Balance Sheet'!D4:D5),"") -> 0.070476136 | E23: =IF(SUM('Balance Sheet'!E4:E5)>0,'Profit & Loss'!E12/SUM('Balance Sheet'!E4:E5),"") -> 0.055674749 | F23: =IF(SUM('Balance Sheet'!F4:F5)>0,'Profit & Loss'!F12/SUM('Balance Sheet'!F4:F5),"") -> 0.033280106 | G23: =IF(SUM('Balance Sheet'!G4:G5)>0,'Profit & Loss'!G12/SUM('Balance Sheet'!G4:G5),"") -> 0.058941788 | H23: =IF(SUM('Balance Sheet'!H4:H5)>0,'Profit & Loss'!H12/SUM('Balance Sheet'!H4:H5),"") -> 0.061800535 | I23: =IF(SUM('Balance Sheet'!I4:I5)>0,'Profit & Loss'!I12/SUM('Balance Sheet'!I4:I5),"") -> 0.073956592 | ... K23: =IF(SUM('Balance Sheet'!K4:K5)>0,'Profit & Loss'!K12/SUM('Balance Sheet'!K4:K5),"") -> 0.063920048
A24: Return on Capital Emp | C24: =IF((B4+B5+B6+C4+C5+C6)>0,('Profit & Loss'!C10+'Profit & Loss'!C9)*2/(B4+B5+B6+C4+C5+C6),"") -> 0.1028425 | D24: =IF((C4+C5+C6+D4+D5+D6)>0,('Profit & Loss'!D10+'Profit & Loss'!D9)*2/(C4+C5+C6+D4+D5+D6),"") -> 0.10505939 | E24: =IF((D4+D5+D6+E4+E5+E6)>0,('Profit & Loss'!E10+'Profit & Loss'!E9)*2/(D4+D5+D6+E4+E5+E6),"") -> 0.095001379 | F24: =IF((E4+E5+E6+F4+F5+F6)>0,('Profit & Loss'!F10+'Profit & Loss'!F9)*2/(E4+E5+E6+F4+F5+F6),"") -> 0.074326976 | G24: =IF((F4+F5+F6+G4+G5+G6)>0,('Profit & Loss'!G10+'Profit & Loss'!G9)*2/(F4+F5+F6+G4+G5+G6),"") -> 0.087411037 | H24: =IF((G4+G5+G6+H4+H5+H6)>0,('Profit & Loss'!H10+'Profit & Loss'!H9)*2/(G4+G5+G6+H4+H5+H6),"") -> 0.093439859 | I24: =IF((H4+H5+H6+I4+I5+I6)>0,('Profit & Loss'!I10+'Profit & Loss'!I9)*2/(H4+H5+H6+I4+I5+I6),"") -> 0.10924669 | J24: =IF((I4+I5+I6+J4+J5+J6)>0,('Profit & Loss'!J10+'Profit & Loss'!J9)*2/(I4+I5+I6+J4+J5+J6),"") -> 0.097593847

Sheet Cash Flow
A1: ='Balance Sheet'!A1 -> TATA CONSUMER PRODUCTS LTD | E1: =UPDATE | J1: SCREENER.IN
A3: Narration | B3: ='Data Sheet'!B81 -> 42460 | C3: ='Data Sheet'!C81 -> 42825 | D3: ='Data Sheet'!D81 -> 43190 | E3: ='Data Sheet'!E81 -> 43555 | F3: ='Data Sheet'!F81 -> 43921 | G3: ='Data Sheet'!G81 -> 44286 | H3: ='Data Sheet'!H81 -> 44651 | I3: ='Data Sheet'!I81 -> 45016 | ... K3: ='Data Sheet'!K81 -> 45747
A4: Cash from Operating Activity | B4: ='Data Sheet'!B82 -> 115.98 | C4: ='Data Sheet'!C82 -> 741.2 | D4: ='Data Sheet'!D82 -> 355.58 | E4: ='Data Sheet'!E82 -> 209.87 | F4: ='Data Sheet'!F82 -> 1082.23 | G4: ='Data Sheet'!G82 -> 1656.37 | H4: ='Data Sheet'!H82 -> 1515.81 | I4: ='Data Sheet'!I82 -> 1461.29 | ... K4: ='Data Sheet'!K82 -> 2056.65
A5: Cash from Investing Activity | B5: ='Data Sheet'!B83 -> 144.62 | C5: ='Data Sheet'!C83 -> 145.05 | D5: ='Data Sheet'!D83 -> -31.1 | E5: ='Data Sheet'!E83 -> 53.17 | F5: ='Data Sheet'!F83 -> -622.04 | G5: ='Data Sheet'!G83 -> -346.5 | H5: ='Data Sheet'!H83 -> -1317.11 | I5: ='Data Sheet'!I83 -> -833.61 | ... K5: ='Data Sheet'!K83 -> -2303.48
A6: Cash from Financing Activity | B6: ='Data Sheet'!B84 -> -281.8 | C6: ='Data Sheet'!C84 -> -815.84 | D6: ='Data Sheet'!D84 -> -30.39 | E6: ='Data Sheet'!E84 -> -223.73 | F6: ='Data Sheet'!F84 -> -308.33 | G6: ='Data Sheet'!G84 -> -426.03 | H6: ='Data Sheet'!H84 -> -994.77 | I6: ='Data Sheet'!I84 -> -714.4 | ... K6: ='Data Sheet'!K84 -> 452.7
A7: Net Cash Flow | B7: ='Data Sheet'!B85 -> -21.2 | C7: ='Data Sheet'!C85 -> 70.41 | D7: ='Data Sheet'!D85 -> 294.09 | E7: ='Data Sheet'!E85 -> 39.31 | F7: ='Data Sheet'!F85 -> 151.86 | G7: ='Data Sheet'!G85 -> 883.84 | H7: ='Data Sheet'!H85 -> -796.07 | I7: ='Data Sheet'!I85 -> -86.72 | ... K7: ='Data Sheet'!K85 -> 205.87

Sheet Customization
A1: How to use it?
A3: You can customize this workbook as you want.
B4: You can add custom formating, add conditional formating, add your own formulas… do ANYTHING.
B5: Please don't edit the "Data Sheet" only.
A7: After customization, you can upload this back on Screener.
B8: Upload on: | C8: https://www.screener.in/excel/
A10: Download your customized workbooks now onwards.
B11: Now whenever you will "Export to excel" from Screener, it will export your customized file.
A14: TESTING:
B15: This is a testing feature currently.
B16: You can report any formula errors on the worksheet at: support@screener.in

Sheet Cash Flow Data
C2: 41609 | D2: 41974 | E2: 42339 | F2: 42705 | G2: 43070 | H2: 43435 | I2: 43800 | J2: 44166 | K2: 44531 | L2: 44896 | M2: 45261 | N2: 45627
B3: Cash from Operating Activity - | C3: 297 | D3: 431 | E3: 555 | F3: 826 | G3: 620 | H3: 1000 | I3: 1308 | J3: 1012 | K3: 1231 | L3: 1790 | M3: 2391 | N3: 3381
B4: Profit from operations | C4: 313 | D4: 397 | E4: 645 | F4: 820 | G4: 873 | H4: 1123 | I4: 1513 | J4: 1200 | K4: 1624 | L4: 2749 | M4: 3732 | N4: 4778
B5: Receivables | C5: 21 | D5: -38 | E5: 0 | F5: 7 | G5: -34 | H5: -13 | I5: -32 | J5: -76 | K5: 15 | L5: -123 | M5: -73 | N5: -133
B6: Inventory | C6: -16 | D6: -43 | E6: -135 | F6: -39 | G6: 45 | H6: -151 | I6: -185 | J6: -47 | K6: -519 | L6: -557 | M6: -160 | N6: -479
B7: Payables | C7: -49 | D7: 86 | E7: 149 | F7: 0 | G7: 0 | H7: 0 | I7: 0 | J7: 0 | K7: 0 | L7: 0 | M7: 0 | N7: 0
B8: Loans Advances | C8: 32 | D8: 39 | E8: -56 | F8: 0 | G8: 0 | H8: 0 | I8: 0 | J8: 0 | K8: 0 | L8: 0 | M8: 0 | N8: 0
B9: Other WC items | C9: 0 | D9: 0 | E9: 0 | F9: 95 | G9: -207 | H9: 114 | I9: 132 | J9: 12 | K9: 236 | L9: 95 | M9: -440 | N9: -57
B10: Working capital changes | C10: -12 | D10: 44 | E10: -42 | F10: 64 | G10: -197 | H10: -50 | I10: -85 | J10: -111 | K10: -269 | L10: -585 | M10: -673 | N10: -669
B11: Direct taxes | C11: -4 | D11: -11 | E11: -48 | F11: -58 | G11: -57 | H11: -73 | I11: -120 | J11: -78 | K11: -124 | L11: -373 | M11: -668 | N11: -728
B12: Cash from Investing Activity - | C12: -574 | D12: -500 | E12: -300 | F12: -1048 | G12: -746 | H12: -937 | I12: -2320 | J12: -472 | K12: -1008 | L12: -1769 | M12: -3288 | N12: -4311
B13: Fixed assets purchased | C13: -578 | D13: -220 | E13: -269 | F13: -792 | G13: -533 | H13: -859 | I13: -754 | J13: -560 | K13: -835 | L13: -1801 | M13: -3264 | N13: -3779
B14: Fixed assets sold | C14: 0 | D14: 0 | E14: 4 | F14: 12 | G14: 17 | H14: 50 | I14: 21 | J14: 24 | K14: 19 | L14: 51 | M14: 70 | N14: 39
... B34: Net Cash Flow | C34: -2 | D34: -11 | E34: 19 | F34: 8 | G34: 32 | H34: -22 | I34: 95 | J34: -33 | K34: 46 | L34: 4 | M34: 88 | N34: 2024
B39: Operating Activities
B40: Profit from operations | C40: 645 | D40: 820 | E40: 873 | F40: 1123 | G40: 1513 | H40: 1200 | I40: 1624 | J40: 2749 | K40: 3732 | L40: 4778
B41: Receivables | C41: 0 | D41: 7 | E41: -34 | F41: -13 | G41: -32 | H41: -76 | I41: 15 | J41: -123 | K41: -73 | L41: -133
B42: Inventory | C42: -135 | D42: -39 | E42: 45 | F42: -151 | G42: -185 | H42: -47 | I42: -519 | J42: -557 | K42: -160 | L42: -479
B43: Payables | C43: 149 | D43: 0 | E43: 0 | F43: 0 | G43: 0 | H43: 0 | I43: 0 | J43: 0 | K43: 0 | L43: 0
B44: Loans Advances | C44: -56 | D44: 0 | E44: 0 | F44: 0 | G44: 0 | H44: 0 | I44: 0 | J44: 0 | K44: 0 | L44: 0
B45: Other WC items | C45: 0 | D45: 95 | E45: -207 | F45: 114 | G45: 132 | H45: 12 | I45: 236 | J45: 95 | K45: -440 | L45: -57
B46: Working capital changes | C46: -42 | D46: 64 | E46: -197 | F46: -50 | G46: -85 | H46: -111 | I46: -269 | J46: -585 | K46: -673 | L46: -669
B47: Direct taxes | C47: -48 | D47: -58 | E47: -57 | F47: -73 | G47: -120 | H47: -78 | I47: -124 | J47: -373 | K47: -668 | L47: -728
B48: Cash from Operating Activities | C48: 513 | D48: 889 | E48: 423 | F48: 950 | G48: 1223 | H48: 900 | I48: 963 | J48: 1206 | K48: 1718 | L48: 2712
B50: Investing Activities
B51: Fixed assets purchased | C51: -269 | D51: -792 | E51: -533 | F51: -859 | G51: -754 | H51: -560 | I51: -835 | J51: -1801 | K51: -3264 | L51: -3779
B52: Fixed assets sold | C52: 4 | D52: 12 | E52: 17 | F52: 50 | G52: 21 | H52: 24 | I52: 19 | J52: 51 | K52: 70 | L52: 39
B53: Investments purchased | C53: -550 | D53: -35 | E53: -35 | F53: 0 | G53: -73 | H53: 0 | I53: 0 | J53: 0 | K53: 0 | L53: 0
B54: Investments sold | C54: 512 | D54: 35 | E54: 35 | F54: 0 | G54: 73 | H54: 0 | I54: 0 | J54: 0 | K54: 0 | L54: 2
B55: Interest received | C55: 6 | D55: 8 | E55: 5 | F55: 6 | G55: 5 | H55: 9 | I55: 13 | J55: 23 | K55: 22 | L55: 28
B56: Dividends received | C56: 0 | D56: 0 | E56: 0 | F56: 0 | G56: 0 | H56: 0 | I56: 0 | J56: 0 | K56: 0 | L56: 0
B57: Investment in group cos | C57: 0 | D57: 0 | E57: 0 | F57: 0 | G57: 0 | H57: 0 | I57: 0 | J57: 0 | K57: -22 | L57: -40
B58: Acquisition of companies | C58: 0 | D58: -276 | E58: -212 | F58: 0 | G58: -8 | H58: 0 | I58: 0 | J58: 0 | K58: -10 | L58: -200
B59: Other investing items | C59: -4 | D59: 0 | E59: -23 | F59: -134 | G59: -1583 | H59: 55 | I59: -205 | J59: -42 | K59: -85 | L59: -361
B60: Cash from Investing Activities | C60: -301 | D60: -1048 | E60: -746 | F60: -937 | G60: -2319 | H60: -472 | I60: -1008 | J60: -1769 | K60: -3289 | L60: -4311
B62: Financing Activities
B63: Proceeds from shares | C63: 0 | D63: 701 | E63: 4 | F63: 1 | G63: 900 | H63: 0 | I63: 0 | J63: 0 | K63: 4 | L63: 7512
B64: Proceeds from debentures | C64: 320 | D64: 180 | E64: 300 | F64: 0 | G64: 0 | H64: 0 | I64: 0 | J64: 0 | K64: 0 | L64: 0
B65: Redemption of debentures | C65: 0 | D65: -500 | E65: 0 | F65: -300 | G65: 0 | H65: 0 | I65: 0 | J65: 0 | K65: 0 | L65: 0
B66: Proceeds from borrowings | C66: 332 | D66: 0 | E66: 0 | F66: 1400 | G66: 1958 | H66: 1020 | I66: 855 | J66: 1478 | K66: 2783 | L66: 1957
...

Sheet Data Sheet
A1: COMPANY NAME | B1: TATA CONSUMER PRODUCTS LTD | E1: =IF(B2<>B3, "A NEW VERSION OF THE WORKSHEET IS AVAILABLE", "")
A2: LATEST VERSION | B2: 2.1 | E2: PLEASE DO NOT MAKE ANY CHANGES TO THIS SHEET
A3: CURRENT VERSION | B3: 2.1
A5: META
A6: Number of shares | B6: =IF(B9>0, B9/B8, 0) -> 98.616099
A7: Face Value | B7: 1
A8: Current Price | B8: 1139.2
A9: Market Capitalization | B9: 112343.46
A15: PROFIT & LOSS
A16: Report Date | B16: 42460 | C16: 42825 | D16: 43190 | E16: 43555 | F16: 43921 | G16: 44286 | H16: 44651 | I16: 45016 | J16: 45382 | K16: 45747
A17: Sales | B17: 6636.54 | C17: 6779.55 | D17: 6815.35 | E17: 7251.5 | F17: 9637.42 | G17: 11602.03 | H17: 12425.37 | I17: 13783.16 | J17: 15205.85 | K17: 17618.3
A18: Raw Material Cost | B18: 3601.49 | C18: 3165.65 | D18: 3746.11 | E18: 4022.05 | F18: 5402.9 | G18: 6367.79 | H18: 6323.22 | I18: 7107.06 | J18: 7364.06 | K18: 8986.68
A19: Change in Inventory | B19: -20.11 | C19: 0.69 | D19: 46.8 | E19: 14.41 | F19: -7.78 | G19: 149.54 | H19: 39.78 | I19: 273.88 | J19: 121.6 | K19: 362.49
A20: Power and Fuel | B20: 81.26 | C20: 83.19 | D20: 87.07 | E20: 89.28 | F20: 103.84 | G20: 97.36 | H20: 123.9 | I20: 149.43 | J20: 156.9 | K20: 156.21
A21: Other Mfr. Exp | B21: 190.32 | C21: 597.61 | D21: 194.69 | E21: 209.59 | F21: 238.47 | G21: 941.75 | H21: 1139.59 | I21: 1578.2 | J21: 1696.28 | K21: 1882.25
A22: Employee Cost | B22: 805.06 | C22: 834.95 | D22: 821.37 | E22: 806.3 | F22: 884.8 | G22: 970.23 | H22: 1048 | I22: 1120.36 | J22: 1258.59 | K22: 1430.1
A23: Selling and admin | B23: 922.88 | C23: 926.92 | D23: 857.64 | E23: 968.23 | F23: 1278.16 | G23: 1421.46 | H23: 1691.83 | I23: 1785.26 | J23: 1927.15 | K23: 2253.37
A24: Other Expenses | B24: 649.51 | C24: 380.79 | D24: 316.36 | E24: 384.55 | F24: 429.32 | G24: 409.22 | H24: 419.83 | I24: 460.26 | J24: 640.37 | K24: 792.83
A25: Other Income | B25: 37.54 | C25: 88.4 | D25: 73.02 | E25: 123.84 | F25: -163.2 | G25: 90.73 | H25: 88 | I25: 328.33 | J25: -81.42 | K25: 188.14
A26: Depreciation | B26: 116.79 | C26: 126.04 | D26: 116.04 | E26: 122.57 | F26: 241.71 | G26: 254.74 | H26: 278.01 | I26: 304.08 | J26: 377.15 | K26: 600.74
A27: Interest | B27: 116.9 | C27: 91.53 | D27: 42.76 | E27: 52.47 | F27: 77.86 | G27: 68.69 | H27: 72.78 | I27: 87.16 | J27: 129.81 | K27: 290.2
... A31: Dividend Amount | B31: 142 | C31: 148.31 | D31: 148.31 | E31: 157.78 | F31: 248.83 | G31: 373.25 | H31: 557.57 | I31: 785 | J31: 738.42 | K31: 816.34
A33: EBITDA | B33: =B30+B29+B27+B26 -> 428.18 | C33: =C30+C29+C27+C26 -> 805.32 | D33: =D30+D29+D27+D26 -> 840.23 | E33: =E30+E29+E27+E26 -> 844.11 | F33: =F30+F29+F27+F26 -> 1053.52 | G33: =G30+G29+G27+G26 -> 1497.39 | H33: =H30+H29+H27+H26 -> 1663.61 | I33: =I30+I29+I27+I26 -> 2042.05 | ... K33: =K30+K29+K27+K26 -> 2565.65
A40: Quarters
A41: Report Date | B41: 45199 | C41: 45291 | D41: 45382 | E41: 45473 | F41: 45565 | G41: 45657 | H41: 45747 | I41: 45838 | J41: 45930 | K41: 46022
A42: Sales | B42: 3733.78 | C42: 3803.92 | D42: 3926.94 | E42: 4352.07 | F42: 4214.45 | G42: 4443.56 | H42: 4608.22 | I42: 4778.91 | J42: 4965.9 | K42: 5112
A43: Expenses | B43: 3196.69 | C43: 3231.54 | D43: 3297.34 | E43: 3684.69 | F43: 3588.16 | G43: 3878.83 | H43: 3987.27 | I43: 4171.97 | J43: 4294.12 | K43: 4391.33
A44: Other Income | B44: 75.28 | C44: -31.94 | D44: -177.35 | E44: 22.07 | F44: 18.8 | G44: 45.44 | H44: 101.83 | I44: 41.17 | J44: 38.01 | K44: 10.15
A45: Depreciation | B45: 93.93 | C45: 85.51 | D45: 115.76 | E45: 148 | F45: 149.33 | G45: 150.32 | H45: 153.09 | I45: 148.93 | J45: 153.28 | K45: 159.29
A46: Interest | B46: 27.56 | C46: 33.19 | D46: 42.83 | E46: 93.6 | F46: 98.69 | G46: 57.92 | H46: 39.99 | I46: 33.76 | J46: 33.23 | K46: 31.62
A47: Profit before tax | B47: 490.88 | C47: 421.74 | D47: 293.66 | E47: 447.85 | F47: 397.07 | G47: 401.93 | H47: 529.7 | I47: 465.42 | J47: 523.28 | K47: 539.91
A48: Tax | B48: 131.7 | C48: 106.21 | D48: 25.95 | E48: 133.7 | F48: 37.73 | G48: 102.18 | H48: 122.63 | I48: 118.98 | J48: 126.23 | K48: 137.12
A49: Net profit | B49: 338.24 | C49: 278.87 | D49: 216.63 | E49: 290.32 | F49: 364.42 | G49: 278.88 | H49: 344.85 | I49: 334.15 | J49: 404.46 | K49: 384.61
A50: Operating Profit | B50: 537.09 | C50: 572.38 | D50: 629.6 | E50: 667.38 | F50: 626.29 | G50: 564.73 | H50: 620.95 | I50: 606.94 | J50: 671.78 | K50: 720.67
A55: BALANCE SHEET
A56: Report Date | B56: 42460 | C56: 42825 | D56: 43190 | E56: 43555 | F56: 43921 | G56: 44286 | H56: 44651 | I56: 45016 | J56: 45382 | K56: 45747
A57: Equity Share Capital | B57: 63.11 | C57: 63.11 | D57: 63.11 | E57: 63.11 | F57: 92.16 | G57: 92.16 | H57: 92.16 | I57: 92.9 | J57: 95.28 | K57: 98.95
A58: Reserves | B58: 6184.06 | C58: 6202.39 | D58: 6968.49 | E58: 7268.58 | F58: 13722.7 | G58: 14442.35 | H58: 15049.78 | I58: 16183.81 | J58: 15961.51 | K58: 19902.13
A59: Borrowings | B59: 1354.05 | C59: 786.56 | D59: 1067.58 | E59: 1141.1 | F59: 1586.32 | G59: 1633.55 | H59: 1412.01 | I59: 1600.04 | J59: 3477.22 | K59: 2392.68
A60: Other Liabilities | B60: 2293.54 | C60: 2499.35 | D60: 2361.58 | E60: 2407.89 | F60: 3071.86 | G60: 4049.76 | H60: 4520.92 | I60: 4885.74 | J60: 8344.78 | K60: 9436.86
...

Sheet Historical FS
B2: ="Historical Financial Statements -"&'Data Sheet'!B1 -> Historical Financial Statements -TATA CONSUMER PRODUCTS LTD
B3: Years | C3: ='Data Sheet'!B16 -> 42460 | D3: ='Data Sheet'!C16 -> 42825 | E3: ='Data Sheet'!D16 -> 43190 | F3: ='Data Sheet'!E16 -> 43555 | G3: ='Data Sheet'!F16 -> 43921 | H3: ='Data Sheet'!G16 -> 44286 | I3: ='Data Sheet'!H16 -> 44651 | J3: ='Data Sheet'!I16 -> 45016 | ... L3: ='Data Sheet'!K16 -> 45747 | M3: LTM
A5: # | B5: Income Statement
B6: Sales | C6: ='Data Sheet'!B17 -> 6636.54 | D6: ='Data Sheet'!C17 -> 6779.55 | E6: ='Data Sheet'!D17 -> 6815.35 | F6: ='Data Sheet'!E17 -> 7251.5 | G6: ='Data Sheet'!F17 -> 9637.42 | H6: ='Data Sheet'!G17 -> 11602.03 | I6: ='Data Sheet'!H17 -> 12425.37 | J6: ='Data Sheet'!I17 -> 13783.16 | ... L6: ='Data Sheet'!K17 -> 17618.3 | M6: =SUM('Data Sheet'!H42:K42) -> 19465.03
B7: Sales Growth | C7: - | D7: =D6/C6-1 -> 0.021548879 | E7: =E6/D6-1 -> 0.0052805865 | F7: =F6/E6-1 -> 0.063995246 | G7: =G6/F6-1 -> 0.32902434 | H7: =H6/G6-1 -> 0.20385228 | I7: =I6/H6-1 -> 0.070965167 | J7: =J6/I6-1 -> 0.10927562 | K7: =K6/J6-1 -> 0.10321944 | ... M7: =M6/L6-1 -> 0.10481885
B9: COGS | C9: =IFERROR(SUM('Data Sheet'!B18,'Data Sheet'!B20:B21),0) -> 3873.07 | D9: =IFERROR(SUM('Data Sheet'!C18,'Data Sheet'!C20:C21),0) -> 3846.45 | E9: =IFERROR(SUM('Data Sheet'!D18,'Data Sheet'!D20:D21),0) -> 4027.87 | F9: =IFERROR(SUM('Data Sheet'!E18,'Data Sheet'!E20:E21),0) -> 4320.92 | G9: =IFERROR(SUM('Data Sheet'!F18,'Data Sheet'!F20:F21),0) -> 5745.21 | H9: =IFERROR(SUM('Data Sheet'!G18,'Data Sheet'!G20:G21),0) -> 7406.9 | I9: =IFERROR(SUM('Data Sheet'!H18,'Data Sheet'!H20:H21),0) -> 7586.71 | J9: =IFERROR(SUM('Data Sheet'!I18,'Data Sheet'!I20:I21),0) -> 8834.69 | ... L9: =IFERROR(SUM('Data Sheet'!K18,'Data Sheet'!K20:K21),0) -> 11025.14 | M9: =IFERROR(SUM('Data Sheet'!H43:K43),0) -> 16844.69
B10: COGS % Sales | C10: =IFERROR(C9/C6,0) -> 0.58359778 | D10: =IFERROR(D9/D6,0) -> 0.56736067 | E10: =IFERROR(E9/E6,0) -> 0.59099973 | F10: =IFERROR(F9/F6,0) -> 0.59586568 | G10: =IFERROR(G9/G6,0) -> 0.59613569 | H10: =IFERROR(H9/H6,0) -> 0.63841414 | I10: =IFERROR(I9/I6,0) -> 0.61058222 | J10: =IFERROR(J9/J6,0) -> 0.64097711 | ... M10: =IFERROR(M9/M6,0) -> 0.86538218
B12: Gross Profit | C12: =IFERROR(C6-C9,0) -> 2763.47 | D12: =IFERROR(D6-D9,0) -> 2933.1 | E12: =IFERROR(E6-E9,0) -> 2787.48 | F12: =IFERROR(F6-F9,0) -> 2930.58 | G12: =IFERROR(G6-G9,0) -> 3892.21 | H12: =IFERROR(H6-H9,0) -> 4195.13 | I12: =IFERROR(I6-I9,0) -> 4838.66 | J12: =IFERROR(J6-J9,0) -> 4948.47 | ... M12: =IFERROR(M6-M9,0) -> 2620.34
B13: Gross Margins | C13: =IFERROR(C12/C6,0) -> 0.41640222 | D13: =IFERROR(D12/D6,0) -> 0.43263933 | E13: =IFERROR(E12/E6,0) -> 0.40900027 | F13: =IFERROR(F12/F6,0) -> 0.40413432 | G13: =IFERROR(G12/G6,0) -> 0.40386431 | H13: =IFERROR(H12/H6,0) -> 0.36158586 | I13: =IFERROR(I12/I6,0) -> 0.38941778 | J13: =IFERROR(J12/J6,0) -> 0.35902289 | ... M13: =IFERROR(M12/M6,0) -> 0.13461782
B15: Selling & General Expenses | C15: =IFERROR(SUM('Data Sheet'!B23:B24),0) -> 1572.39 | D15: =IFERROR(SUM('Data Sheet'!C23:C24),0) -> 1307.71 | E15: =IFERROR(SUM('Data Sheet'!D23:D24),0) -> 1174 | F15: =IFERROR(SUM('Data Sheet'!E23:E24),0) -> 1352.78 | G15: =IFERROR(SUM('Data Sheet'!F23:F24),0) -> 1707.48 | H15: =IFERROR(SUM('Data Sheet'!G23:G24),0) -> 1830.68 | I15: =IFERROR(SUM('Data Sheet'!H23:H24),0) -> 2111.66 | J15: =IFERROR(SUM('Data Sheet'!I23:I24),0) -> 2245.52 | ... L15: =IFERROR(SUM('Data Sheet'!K23:K24),0) -> 3046.2 | M15: -
B16: S&G Exp % Sales | C16: =IFERROR(C15/C6,0) -> 0.23692918 | D16: =IFERROR(D15/D6,0) -> 0.19289038 | E16: =IFERROR(E15/E6,0) -> 0.17225821 | F16: =IFERROR(F15/F6,0) -> 0.18655175 | G16: =IFERROR(G15/G6,0) -> 0.1771719 | H16: =IFERROR(H15/H6,0) -> 0.15778963 | I16: =IFERROR(I15/I6,0) -> 0.16994745 | J16: =IFERROR(J15/J6,0) -> 0.16291765 | ... M16: =IFERROR(M15/M6,0) -> 0
B18: EBITDA | C18: =IFERROR(C12-C15,0) -> 1191.08 | D18: =IFERROR(D12-D15,0) -> 1625.39 | E18: =IFERROR(E12-E15,0) -> 1613.48 | F18: =IFERROR(F12-F15,0) -> 1577.8 | G18: =IFERROR(G12-G15,0) -> 2184.73 | H18: =IFERROR(H12-H15,0) -> 2364.45 | I18: =IFERROR(I12-I15,0) -> 2727 | J18: =IFERROR(J12-J15,0) -> 2702.95 | ... L18: =IFERROR(L12-L15,0) -> 3546.96 | M18: =IFERROR(SUM('Data Sheet'!H50:K50,'Data Sheet'!H45:K45),0) -> 3234.93
B19: EBITDA Margins | C19: =IFERROR(C18/C6,0) -> 0.17947304 | D19: =IFERROR(D18/D6,0) -> 0.23974895 | E19: =IFERROR(E18/E6,0) -> 0.23674206 | F19: =IFERROR(F18/F6,0) -> 0.21758257 | G19: =IFERROR(G18/G6,0) -> 0.22669241 | H19: =IFERROR(H18/H6,0) -> 0.20379623 | I19: =IFERROR(I18/I6,0) -> 0.21947033 | J19: =IFERROR(J18/J6,0) -> 0.19610525 | ... M19: =IFERROR(M18/M6,0) -> 0.16619188
B21: Interest | C21: =IFERROR('Data Sheet'!B27,0) -> 116.9 | D21: =IFERROR('Data Sheet'!C27,0) -> 91.53 | E21: =IFERROR('Data Sheet'!D27,0) -> 42.76 | F21: =IFERROR('Data Sheet'!E27,0) -> 52.47 | G21: =IFERROR('Data Sheet'!F27,0) -> 77.86 | H21: =IFERROR('Data Sheet'!G27,0) -> 68.69 | I21: =IFERROR('Data Sheet'!H27,0) -> 72.78 | J21: =IFERROR('Data Sheet'!I27,0) -> 87.16 | ... L21: =IFERROR('Data Sheet'!K27,0) -> 290.2 | M21: =IFERROR(SUM('Data Sheet'!H46:K46),0) -> 138.6
B22: Interest % Sales | C22: =IFERROR(C21/C6,0) -> 0.0176146 | D22: =IFERROR(D21/D6,0) -> 0.013500896 | E22: =IFERROR(E21/E6,0) -> 0.0062740725 | F22: =IFERROR(F21/F6,0) -> 0.0072357443 | G22: =IFERROR(G21/G6,0) -> 0.0080789257 | H22: =IFERROR(H21/H6,0) -> 0.0059205156 | I22: =IFERROR(I21/I6,0) -> 0.0058573708 | J22: =IFERROR(J21/J6,0) -> 0.0063236587 | ... M22: =IFERROR(M21/M6,0) -> 0.0071204617
B24: Depreciation | C24: =IFERROR('Data Sheet'!B26,0) -> 116.79 | D24: =IFERROR('Data Sheet'!C26,0) -> 126.04 | E24: =IFERROR('Data Sheet'!D26,0) -> 116.04 | F24: =IFERROR('Data Sheet'!E26,0) -> 122.57 | G24: =IFERROR('Data Sheet'!F26,0) -> 241.71 | H24: =IFERROR('Data Sheet'!G26,0) -> 254.74 | I24: =IFERROR('Data Sheet'!H26,0) -> 278.01 | J24: =IFERROR('Data Sheet'!I26,0) -> 304.08 | ... L24: =IFERROR('Data Sheet'!K26,0) -> 600.74 | M24: =IFERROR(SUM('Data Sheet'!H45:K45),0) -> 614.59
B25: Depreciation % Sales | C25: =IFERROR(C24/C6,0) -> 0.017598025 | D25: =IFERROR(D24/D6,0) -> 0.018591204 | E25: =IFERROR(E24/E6,0) -> 0.017026272 | F25: =IFERROR(F24/F6,0) -> 0.01690271 | G25: =IFERROR(G24/G6,0) -> 0.025080364 | H25: =IFERROR(H24/H6,0) -> 0.021956502 | I25: =IFERROR(I24/I6,0) -> 0.022374384 | J25: =IFERROR(J24/J6,0) -> 0.022061704 | ... M25: =IFERROR(M24/M6,0) -> 0.031574059
B27: Earnings Before Tax | C27: =IFERROR(C18-1*SUM(C24,C21),0) -> 957.39 | D27: =IFERROR(D18-1*SUM(D24,D21),0) -> 1407.82 | E27: =IFERROR(E18-1*SUM(E24,E21),0) -> 1454.68 | F27: =IFERROR(F18-1*SUM(F24,F21),0) -> 1402.76 | G27: =IFERROR(G18-1*SUM(G24,G21),0) -> 1865.16 | H27: =IFERROR(H18-1*SUM(H24,H21),0) -> 2041.02 | I27: =IFERROR(I18-1*SUM(I24,I21),0) -> 2376.21 | J27: =IFERROR(J18-1*SUM(J24,J21),0) -> 2311.71 | ... M27: =IFERROR(M18-1*SUM(M24,M21),0) -> 2481.74
B28: EBT % Sales | C28: =IFERROR(C27/C6,0) -> 0.14426041 | D28: =IFERROR(D27/D6,0) -> 0.20765685 | E28: =IFERROR(E27/E6,0) -> 0.21344172 | F28: =IFERROR(F27/F6,0) -> 0.19344412 | G28: =IFERROR(G27/G6,0) -> 0.19353312 | H28: =IFERROR(H27/H6,0) -> 0.17591921 | I28: =IFERROR(I27/I6,0) -> 0.19123857 | J28: =IFERROR(J27/J6,0) -> 0.16771988 | ... M28: =IFERROR(M27/M6,0) -> 0.12749736
B30: Tax | C30: =IFERROR('Data Sheet'!B29,0) -> 200.01 | D30: =IFERROR('Data Sheet'!C29,0) -> 198.31 | E30: =IFERROR('Data Sheet'!D29,0) -> 185.87 | F30: =IFERROR('Data Sheet'!E29,0) -> 260.88 | G30: =IFERROR('Data Sheet'!F29,0) -> 274.19 | H30: =IFERROR('Data Sheet'!G29,0) -> 317.27 | I30: =IFERROR('Data Sheet'!H29,0) -> 377.04 | J30: =IFERROR('Data Sheet'!I29,0) -> 447.04 | ... L30: =IFERROR('Data Sheet'!K29,0) -> 396.24 | M30: =IFERROR(SUM('Data Sheet'!H48:K48),0) -> 504.96
B31: Effective Tax Rate | C31: =IFERROR(C30/C27,0) -> 0.20891173 | D31: =IFERROR(D30/D27,0) -> 0.14086318 | E31: =IFERROR(E30/E27,0) -> 0.12777381 | F31: =IFERROR(F30/F27,0) -> 0.18597622 | G31: =IFERROR(G30/G27,0) -> 0.14700615 | H31: =IFERROR(H30/H27,0) -> 0.15544679 | I31: =IFERROR(I30/I27,0) -> 0.15867284 | J31: =IFERROR(J30/J27,0) -> 0.19338066 | ... M31: =IFERROR(M30/M27,0) -> 0.20347015
B33: Net Profit | C33: =IFERROR(C27-C30,0) -> 757.38 | D33: =IFERROR(D27-D30,0) -> 1209.51 | E33: =IFERROR(E27-E30,0) -> 1268.81 | F33: =IFERROR(F27-F30,0) -> 1141.88 | G33: =IFERROR(G27-G30,0) -> 1590.97 | H33: =IFERROR(H27-H30,0) -> 1723.75 | I33: =IFERROR(I27-I30,0) -> 1999.17 | J33: =IFERROR(J27-J30,0) -> 1864.67 | ... M33: =IFERROR(M27-M30,0) -> 1976.78
B34: Net Margins | C34: =IFERROR(C33/C6,0) -> 0.11412272 | D34: =IFERROR(D33/D6,0) -> 0.17840565 | E34: =IFERROR(E33/E6,0) -> 0.18616946 | F34: =IFERROR(F33/F6,0) -> 0.15746811 | G34: =IFERROR(G33/G6,0) -> 0.16508256 | H34: =IFERROR(H33/H6,0) -> 0.14857314 | I34: =IFERROR(I33/I6,0) -> 0.1608942 | J34: =IFERROR(J33/J6,0) -> 0.1352861 | ... M34: =IFERROR(M33/M6,0) -> 0.10155546
B36: No. of Equity Shares | C36: =IFERROR('Data Sheet'!B93,0) -> 65.54 | D36: =IFERROR('Data Sheet'!C93,0) -> 65.54 | E36: =IFERROR('Data Sheet'!D93,0) -> 65.54 | F36: =IFERROR('Data Sheet'!E93,0) -> 65.54 | G36: =IFERROR('Data Sheet'!F93,0) -> 95.7 | H36: =IFERROR('Data Sheet'!G93,0) -> 95.7 | I36: =IFERROR('Data Sheet'!H93,0) -> 95.7 | J36: =IFERROR('Data Sheet'!I93,0) -> 96.47 | ... L36: =IFERROR('Data Sheet'!K93,0) -> 98.95 | M36: -
B38: Earnings per Share | C38: =IFERROR(C33/C36,0) -> 11.555996 | D38: =IFERROR(D33/D36,0) -> 18.454532 | E38: =IFERROR(E33/E36,0) -> 19.359323 | F38: =IFERROR(F33/F36,0) -> 17.422643 | G38: =IFERROR(G33/G36,0) -> 16.624556 | H38: =IFERROR(H33/H36,0) -> 18.012017 | I38: =IFERROR(I33/I36,0) -> 20.889969 | J38: =IFERROR(J33/J36,0) -> 19.329014 | ... M38: =IFERROR(M33/M36,0) -> 0
B39: EPS Growth | C39: - | D39: =IFERROR(D38/C38-1,0) -> 0.59696586 | E39: =IFERROR(E38/D38-1,0) -> 0.049028119 | F39: =IFERROR(F38/E38-1,0) -> -0.10003862 | G39: =IFERROR(G38/F38-1,0) -> -0.045807446 | H39: =IFERROR(H38/G38-1,0) -> 0.083458519 | I39: =IFERROR(I38/H38-1,0) -> 0.15977955 | J39: =IFERROR(J38/I38-1,0) -> -0.07472268 | K39: =IFERROR(K38/J38-1,0) -> 0.31726036 | ... M39: =IFERROR(M38/L38-1,0) -> -1
B41: Dividend per Share | C41: =IFERROR('Data Sheet'!B31/'Data Sheet'!B93,0) -> 2.1666158 | D41: =IFERROR('Data Sheet'!C31/'Data Sheet'!C93,0) -> 2.2628929 | E41: =IFERROR('Data Sheet'!D31/'Data Sheet'!D93,0) -> 2.2628929 | F41: =IFERROR('Data Sheet'!E31/'Data Sheet'!E93,0) -> 2.4073848 | G41: =IFERROR('Data Sheet'!F31/'Data Sheet'!F93,0) -> 2.6001045 | H41: =IFERROR('Data Sheet'!G31/'Data Sheet'!G93,0) -> 3.900209 | I41: =IFERROR('Data Sheet'!H31/'Data Sheet'!H93,0) -> 5.8262278 | J41: =IFERROR('Data Sheet'!I31/'Data Sheet'!I93,0) -> 8.1372447 | ... L41: =IFERROR('Data Sheet'!K31/'Data Sheet'!K93,0) -> 8.2500253 | M41: -
B42: Dividend Payout Ratio | C42: =IFERROR(C41/C38,0) -> 0.18748845 | D42: =IFERROR(D41/D38,0) -> 0.1226199 | E42: =IFERROR(E41/E38,0) -> 0.11688905 | F42: =IFERROR(F41/F38,0) -> 0.13817564 | G42: =IFERROR(G41/G38,0) -> 0.15640144 | H42: =IFERROR(H41/H38,0) -> 0.21653372 | I42: =IFERROR(I41/I38,0) -> 0.27890074 | J42: =IFERROR(J41/J38,0) -> 0.42098602 | ... M42: =IFERROR(M41/M38,0) -> 0
B44: Retained Earnings | C44: =IFERROR(IF(C38>C41,1-C42,0),0) -> 0.81251155 | D44: =IFERROR(IF(D38>D41,1-D42,0),0) -> 0.8773801 | E44: =IFERROR(IF(E38>E41,1-E42,0),0) -> 0.88311095 | F44: =IFERROR(IF(F38>F41,1-F42,0),0) -> 0.86182436 | G44: =IFERROR(IF(G38>G41,1-G42,0),0) -> 0.84359856 | H44: =IFERROR(IF(H38>H41,1-H42,0),0) -> 0.78346628 | I44: =IFERROR(IF(I38>I41,1-I42,0),0) -> 0.72109926 | J44: =IFERROR(IF(J38>J41,1-J42,0),0) -> 0.57901398 | ... M44: =IFERROR(IF(M38>M41,1-M42,0),0) -> 0
A46: # | B46: Balance Sheet
B48: ='Data Sheet'!A57 -> Equity Share Capital | C48: =IFERROR('Data Sheet'!B57,0) -> 63.11 | D48: =IFERROR('Data Sheet'!C57,0) -> 63.11 | E48: =IFERROR('Data Sheet'!D57,0) -> 63.11 | F48: =IFERROR('Data Sheet'!E57,0) -> 63.11 | G48: =IFERROR('Data Sheet'!F57,0) -> 92.16 | H48: =IFERROR('Data Sheet'!G57,0) -> 92.16 | I48: =IFERROR('Data Sheet'!H57,0) -> 92.16 | J48: =IFERROR('Data Sheet'!I57,0) -> 92.9 | ... L48: =IFERROR('Data Sheet'!K57,0) -> 98.95
B49: ='Data Sheet'!A58 -> Reserves | C49: =IFERROR('Data Sheet'!B58,0) -> 6184.06 | D49: =IFERROR('Data Sheet'!C58,0) -> 6202.39 | E49: =IFERROR('Data Sheet'!D58,0) -> 6968.49 | F49: =IFERROR('Data Sheet'!E58,0) -> 7268.58 | G49: =IFERROR('Data Sheet'!F58,0) -> 13722.7 | H49: =IFERROR('Data Sheet'!G58,0) -> 14442.35 | I49: =IFERROR('Data Sheet'!H58,0) -> 15049.78 | J49: =IFERROR('Data Sheet'!I58,0) -> 16183.81 | ... L49: =IFERROR('Data Sheet'!K58,0) -> 19902.13
B50: ='Data Sheet'!A59 -> Borrowings | C50: =IFERROR('Data Sheet'!B59,0) -> 1354.05 | D50: =IFERROR('Data Sheet'!C59,0) -> 786.56 | E50: =IFERROR('Data Sheet'!D59,0) -> 1067.58 | F50: =IFERROR('Data Sheet'!E59,0) -> 1141.1 | G50: =IFERROR('Data Sheet'!F59,0) -> 1586.32 | H50: =IFERROR('Data Sheet'!G59,0) -> 1633.55 | I50: =IFERROR('Data Sheet'!H59,0) -> 1412.01 | J50: =IFERROR('Data Sheet'!I59,0) -> 1600.04 | ... L50: =IFERROR('Data Sheet'!K59,0) -> 2392.68
B51: ='Data Sheet'!A60 -> Other Liabilities | C51: =IFERROR('Data Sheet'!B60,0) -> 2293.54 | D51: =IFERROR('Data Sheet'!C60,0) -> 2499.35 | E51: =IFERROR('Data Sheet'!D60,0) -> 2361.58 | F51: =IFERROR('Data Sheet'!E60,0) -> 2407.89 | G51: =IFERROR('Data Sheet'!F60,0) -> 3071.86 | H51: =IFERROR('Data Sheet'!G60,0) -> 4049.76 | I51: =IFERROR('Data Sheet'!H60,0) -> 4520.92 | J51: =IFERROR('Data Sheet'!I60,0) -> 4885.74 | ... L51: =IFERROR('Data Sheet'!K60,0) -> 9436.86
B52: Total Liabilities | C52: =IFERROR('Data Sheet'!B61,0) -> 9894.76 | D52: =IFERROR('Data Sheet'!C61,0) -> 9551.41 | E52: =IFERROR('Data Sheet'!D61,0) -> 10460.76 | F52: =IFERROR('Data Sheet'!E61,0) -> 10880.68 | G52: =IFERROR('Data Sheet'!F61,0) -> 18473.04 | H52: =IFERROR('Data Sheet'!G61,0) -> 20217.82 | I52: =IFERROR('Data Sheet'!H61,0) -> 21074.87 | J52: =IFERROR('Data Sheet'!I61,0) -> 22762.49 | ... L52: =IFERROR('Data Sheet'!K61,0) -> 31830.62
B54: Fixed Assets Net Block | C54: =IFERROR('Data Sheet'!B62,0) -> 4661.8 | D54: =IFERROR('Data Sheet'!C62,0) -> 4572.59 | E54: =IFERROR('Data Sheet'!D62,0) -> 4798.18 | F54: =IFERROR('Data Sheet'!E62,0) -> 4913.31 | G54: =IFERROR('Data Sheet'!F62,0) -> 11656.04 | H54: =IFERROR('Data Sheet'!G62,0) -> 12023.13 | I54: =IFERROR('Data Sheet'!H62,0) -> 12599.35 | J54: =IFERROR('Data Sheet'!I62,0) -> 13070.04 | ... L54: =IFERROR('Data Sheet'!K62,0) -> 21476.84
B55: ='Data Sheet'!A63 -> Capital Work in Progress | C55: =IFERROR('Data Sheet'!B63,0) -> 39.42 | D55: =IFERROR('Data Sheet'!C63,0) -> 63.19 | E55: =IFERROR('Data Sheet'!D63,0) -> 135.16 | F55: =IFERROR('Data Sheet'!E63,0) -> 424.41 | G55: =IFERROR('Data Sheet'!F63,0) -> 95.35 | H55: =IFERROR('Data Sheet'!G63,0) -> 112.85 | I55: =IFERROR('Data Sheet'!H63,0) -> 246.97 | J55: =IFERROR('Data Sheet'!I63,0) -> 294.9 | ... L55: =IFERROR('Data Sheet'!K63,0) -> 218.1
B56: ='Data Sheet'!A64 -> Investments | C56: =IFERROR('Data Sheet'!B64,0) -> 1365.94 | D56: =IFERROR('Data Sheet'!C64,0) -> 1451.04 | E56: =IFERROR('Data Sheet'!D64,0) -> 1161.33 | F56: =IFERROR('Data Sheet'!E64,0) -> 1187.66 | G56: =IFERROR('Data Sheet'!F64,0) -> 1322.85 | H56: =IFERROR('Data Sheet'!G64,0) -> 805.89 | I56: =IFERROR('Data Sheet'!H64,0) -> 797.28 | J56: =IFERROR('Data Sheet'!I64,0) -> 1432.97 | ... L56: =IFERROR('Data Sheet'!K64,0) -> 968.67
B57: ='Data Sheet'!A65 -> Other Assets | C57: =IFERROR('Data Sheet'!B65-1*(SUM('Historical FS'!C60:C62)),0) -> 1105.13 | D57: =IFERROR('Data Sheet'!C65-1*(SUM('Historical FS'!D60:D62)),0) -> 844.36 | E57: =IFERROR('Data Sheet'!D65-1*(SUM('Historical FS'!E60:E62)),0) -> 1031.36 | F57: =IFERROR('Data Sheet'!E65-1*(SUM('Historical FS'!F60:F62)),0) -> 1032.6 | G57: =IFERROR('Data Sheet'!F65-1*(SUM('Historical FS'!G60:G62)),0) -> 1142.9 | H57: =IFERROR('Data Sheet'!G65-1*(SUM('Historical FS'!H60:H62)),0) -> 1190.59 | I57: =IFERROR('Data Sheet'!H65-1*(SUM('Historical FS'!I60:I62)),0) -> 1729.72 | J57: =IFERROR('Data Sheet'!I65-1*(SUM('Historical FS'!J60:J62)),0) -> 1667.64 | ... L57: =IFERROR('Data Sheet'!K65-1*(SUM('Historical FS'!L60:L62)),0) -> 1879.45
B58: Total Non Current Assets | C58: =IFERROR(SUM(C54:C57),0) -> 7172.29 | D58: =IFERROR(SUM(D54:D57),0) -> 6931.18 | E58: =IFERROR(SUM(E54:E57),0) -> 7126.03 | F58: =IFERROR(SUM(F54:F57),0) -> 7557.98 | G58: =IFERROR(SUM(G54:G57),0) -> 14217.14 | H58: =IFERROR(SUM(H54:H57),0) -> 14132.46 | I58: =IFERROR(SUM(I54:I57),0) -> 15373.32 | J58: =IFERROR(SUM(J54:J57),0) -> 16465.55 | ... L58: =IFERROR(SUM(L54:L57),0) -> 24543.06
...

Sheet Ratio Analysis
B2: ="Ratio Analysis - "&'Data Sheet'!B1 -> Ratio Analysis - TATA CONSUMER PRODUCTS LTD
B3: Years | C3: ='Data Sheet'!B16 -> 42460 | D3: ='Data Sheet'!C16 -> 42825 | E3: ='Data Sheet'!D16 -> 43190 | F3: ='Data Sheet'!E16 -> 43555 | G3: ='Data Sheet'!F16 -> 43921 | H3: ='Data Sheet'!G16 -> 44286 | I3: ='Data Sheet'!H16 -> 44651 | J3: ='Data Sheet'!I16 -> 45016 | K3: ='Data Sheet'!J16 -> 45382 | L3: Trend | M3: Mean | N3: Median
B5: Sales Growth | D5: =IFERROR('Historical FS'!D7,0) -> 0.021548879 | E5: =IFERROR('Historical FS'!E7,0) -> 0.0052805865 | F5: =IFERROR('Historical FS'!F7,0) -> 0.063995246 | G5: =IFERROR('Historical FS'!G7,0) -> 0.32902434 | H5: =IFERROR('Historical FS'!H7,0) -> 0.20385228 | I5: =IFERROR('Historical FS'!I7,0) -> 0.070965167 | J5: =IFERROR('Historical FS'!J7,0) -> 0.10927562 | K5: =IFERROR('Historical FS'!K7,0) -> 0.10321944 | M5: =IFERROR(AVERAGE(D5:K5),0) -> 0.11339519 | N5: =IFERROR(MEDIAN(D5:K5),0) -> 0.087092302
B6: EBITDA Growth | D6: =IFERROR('Historical FS'!D18/'Historical FS'!C18-1,0) -> 0.36463546 | E6: =IFERROR('Historical FS'!E18/'Historical FS'!D18-1,0) -> -0.0073274722 | F6: =IFERROR('Historical FS'!F18/'Historical FS'!E18-1,0) -> -0.022113692 | G6: =IFERROR('Historical FS'!G18/'Historical FS'!F18-1,0) -> 0.38466853 | H6: =IFERROR('Historical FS'!H18/'Historical FS'!G18-1,0) -> 0.082261881 | I6: =IFERROR('Historical FS'!I18/'Historical FS'!H18-1,0) -> 0.15333376 | J6: =IFERROR('Historical FS'!J18/'Historical FS'!I18-1,0) -> -0.0088192153 | K6: =IFERROR('Historical FS'!K18/'Historical FS'!J18-1,0) -> 0.26568749 | M6: =IFERROR(AVERAGE(D6:K6),0) -> 0.15154084 | N6: =IFERROR(MEDIAN(D6:K6),0) -> 0.11779782
B7: EBIT Growth | D7: =IFERROR(('Historical FS'!D18-'Historical FS'!D24)/('Historical FS'!C18-'Historical FS'!C24)-1,0) -> 0.39566597 | E7: =IFERROR(('Historical FS'!E18-'Historical FS'!E24)/('Historical FS'!D18-'Historical FS'!D24)-1,0) -> -0.0012738854 | F7: =IFERROR(('Historical FS'!F18-'Historical FS'!F24)/('Historical FS'!E18-'Historical FS'!E24)-1,0) -> -0.028188108 | G7: =IFERROR(('Historical FS'!G18-'Historical FS'!G24)/('Historical FS'!F18-'Historical FS'!F24)-1,0) -> 0.33519787 | H7: =IFERROR(('Historical FS'!H18-'Historical FS'!H24)/('Historical FS'!G18-'Historical FS'!G24)-1,0) -> 0.085789132 | I7: =IFERROR(('Historical FS'!I18-'Historical FS'!I24)/('Historical FS'!H18-'Historical FS'!H24)-1,0) -> 0.16081831 | J7: =IFERROR(('Historical FS'!J18-'Historical FS'!J24)/('Historical FS'!I18-'Historical FS'!I24)-1,0) -> -0.02046558 | K7: =IFERROR(('Historical FS'!K18-'Historical FS'!K24)/('Historical FS'!J18-'Historical FS'!J24)-1,0) -> 0.26890578 | M7: =IFERROR(AVERAGE(D7:K7),0) -> 0.14955619 | N7: =IFERROR(MEDIAN(D7:K7),0) -> 0.12330372
B8: Net Profit Growth | D8: =IFERROR('Historical FS'!D33/'Historical FS'!C33-1,0) -> 0.59696586 | E8: =IFERROR('Historical FS'!E33/'Historical FS'!D33-1,0) -> 0.049028119 | F8: =IFERROR('Historical FS'!F33/'Historical FS'!E33-1,0) -> -0.10003862 | G8: =IFERROR('Historical FS'!G33/'Historical FS'!F33-1,0) -> 0.39329001 | H8: =IFERROR('Historical FS'!H33/'Historical FS'!G33-1,0) -> 0.083458519 | I8: =IFERROR('Historical FS'!I33/'Historical FS'!H33-1,0) -> 0.15977955 | J8: =IFERROR('Historical FS'!J33/'Historical FS'!I33-1,0) -> -0.06727792 | K8: =IFERROR('Historical FS'!K33/'Historical FS'!J33-1,0) -> 0.35112379 | M8: =IFERROR(AVERAGE(D8:K8),0) -> 0.18329116 | N8: =IFERROR(MEDIAN(D8:K8),0) -> 0.12161903
B9: Dividend Growth | D9: =IFERROR('Historical FS'!D41/'Historical FS'!C41-1,0) -> 0.04443662 | E9: =IFERROR('Historical FS'!E41/'Historical FS'!D41-1,0) -> 0 | F9: =IFERROR('Historical FS'!F41/'Historical FS'!E41-1,0) -> 0.063852741 | G9: =IFERROR('Historical FS'!G41/'Historical FS'!F41-1,0) -> 0.080053546 | H9: =IFERROR('Historical FS'!H41/'Historical FS'!G41-1,0) -> 0.50002009 | I9: =IFERROR('Historical FS'!I41/'Historical FS'!H41-1,0) -> 0.49382451 | J9: =IFERROR('Historical FS'!J41/'Historical FS'!I41-1,0) -> 0.3966575 | K9: =IFERROR('Historical FS'!K41/'Historical FS'!J41-1,0) -> -0.082913555 | M9: =IFERROR(AVERAGE(D9:K9),0) -> 0.18699143 | N9: =IFERROR(MEDIAN(D9:K9),0) -> 0.071953143
B11: Gross Margin | C11: =IFERROR('Historical FS'!C13,0) -> 0.41640222 | D11: =IFERROR('Historical FS'!D13,0) -> 0.43263933 | E11: =IFERROR('Historical FS'!E13,0) -> 0.40900027 | F11: =IFERROR('Historical FS'!F13,0) -> 0.40413432 | G11: =IFERROR('Historical FS'!G13,0) -> 0.40386431 | H11: =IFERROR('Historical FS'!H13,0) -> 0.36158586 | I11: =IFERROR('Historical FS'!I13,0) -> 0.38941778 | J11: =IFERROR('Historical FS'!J13,0) -> 0.35902289 | K11: =IFERROR('Historical FS'!K13,0) -> 0.39383592 | M11: =IFERROR(AVERAGE(D11:K11),0) -> 0.39418759 | N11: =IFERROR(MEDIAN(D11:K11),0) -> 0.39885012
B12: EBITDA Margin | C12: =IFERROR('Historical FS'!C19,0) -> 0.17947304 | D12: =IFERROR('Historical FS'!D19,0) -> 0.23974895 | E12: =IFERROR('Historical FS'!E19,0) -> 0.23674206 | F12: =IFERROR('Historical FS'!F19,0) -> 0.21758257 | G12: =IFERROR('Historical FS'!G19,0) -> 0.22669241 | H12: =IFERROR('Historical FS'!H19,0) -> 0.20379623 | I12: =IFERROR('Historical FS'!I19,0) -> 0.21947033 | J12: =IFERROR('Historical FS'!J19,0) -> 0.19610525 | K12: =IFERROR('Historical FS'!K19,0) -> 0.22498512 | M12: =IFERROR(AVERAGE(D12:K12),0) -> 0.22064036 | N12: =IFERROR(MEDIAN(D12:K12),0) -> 0.22222772
B13: EBIT Margin | C13: =IFERROR(('Historical FS'!C18-'Historical FS'!C24)/'Historical FS'!C6,0) -> 0.16187501 | D13: =IFERROR(('Historical FS'!D18-'Historical FS'!D24)/'Historical FS'!D6,0) -> 0.22115775 | E13: =IFERROR(('Historical FS'!E18-'Historical FS'!E24)/'Historical FS'!E6,0) -> 0.21971579 | F13: =IFERROR(('Historical FS'!F18-'Historical FS'!F24)/'Historical FS'!F6,0) -> 0.20067986 | G13: =IFERROR(('Historical FS'!G18-'Historical FS'!G24)/'Historical FS'!G6,0) -> 0.20161205 | H13: =IFERROR(('Historical FS'!H18-'Historical FS'!H24)/'Historical FS'!H6,0) -> 0.18183973 | I13: =IFERROR(('Historical FS'!I18-'Historical FS'!I24)/'Historical FS'!I6,0) -> 0.19709594 | J13: =IFERROR(('Historical FS'!J18-'Historical FS'!J24)/'Historical FS'!J6,0) -> 0.17404354 | K13: =IFERROR(('Historical FS'!K18-'Historical FS'!K24)/'Historical FS'!K6,0) -> 0.20018217 | M13: =IFERROR(AVERAGE(D13:K13),0) -> 0.19954085 | N13: =IFERROR(MEDIAN(D13:K13),0) -> 0.20043101
