Workbook
Name UPDATE: 'Data Sheet'!$E$1

Sheet Profit & Loss
A1: ='Data Sheet'!B1 -> HDFC BANK LTD | H1: =UPDATE | M1: SCREENER.IN
A3: Narration | B3: ='Data Sheet'!B16 -> 42825 | C3: ='Data Sheet'!C16 -> 43190 | D3: ='Data Sheet'!D16 -> 43555 | E3: ='Data Sheet'!E16 -> 43921 | F3: ='Data Sheet'!F16 -> 44286 | G3: ='Data Sheet'!G16 -> 44651 | H3: ='Data Sheet'!H16 -> 45016 | I3: ='Data Sheet'!I16 -> 45382 | ... K3: ='Data Sheet'!K16 -> 46112 | L3: Trailing | M3: Best Case | N3: Worst Case
A4: Sales | B4: ='Data Sheet'!B17 -> 73271.35 | C4: ='Data Sheet'!C17 -> 85287.84 | D4: ='Data Sheet'!D17 -> 105160.74 | E4: ='Data Sheet'!E17 -> 122189.29 | F4: ='Data Sheet'!F17 -> 128552.4 | G4: ='Data Sheet'!G17 -> 135936.41 | H4: ='Data Sheet'!H17 -> 170754.05 | I4: ='Data Sheet'!I17 -> 283649.02 | ... K4: ='Data Sheet'!K17 -> 348615.15 | L4: =SUM(Quarters!H4:K4) -> 348615.15 | M4: =$K4+M23*K4 -> 442253.56 | N4: =$K4+N23*L4 -> 361308.83
A5: Expenses | B5: =SUM('Data Sheet'!B18,'Data Sheet'!B20:B24, -1*'Data Sheet'!B19) -> 23855.69 | C5: =SUM('Data Sheet'!C18,'Data Sheet'!C20:C24, -1*'Data Sheet'!C19) -> 29532.26 | D5: =SUM('Data Sheet'!D18,'Data Sheet'!D20:D24, -1*'Data Sheet'!D19) -> 34856.27 | E5: =SUM('Data Sheet'!E18,'Data Sheet'!E20:E24, -1*'Data Sheet'!E19) -> 45459.21 | F5: =SUM('Data Sheet'!F18,'Data Sheet'!F20:F24, -1*'Data Sheet'!F19) -> 52456.53 | G5: =SUM('Data Sheet'!G18,'Data Sheet'!G20:G24, -1*'Data Sheet'!G19) -> 56556.96 | H5: =SUM('Data Sheet'!H18,'Data Sheet'!H20:H24, -1*'Data Sheet'!H19) -> 63042.3 | I5: =SUM('Data Sheet'!I18,'Data Sheet'!I20:I24, -1*'Data Sheet'!I19) -> 174195.54 | ... K5: =SUM('Data Sheet'!K18,'Data Sheet'!K20:K24, -1*'Data Sheet'!K19) -> 207830.13 | L5: =SUM(Quarters!H5:K5) -> 207830.13 | M5: =M4-M6 -> 259791.57 | N5: =N4-N6 -> 215397.58
A6: Operating Profit | B6: =B4-B5 -> 49415.66 | C6: =C4-C5 -> 55755.58 | D6: =D4-D5 -> 70304.47 | E6: =E4-E5 -> 76730.08 | F6: =F4-F5 -> 76095.87 | G6: =G4-G5 -> 79379.45 | H6: =H4-H5 -> 107711.75 | I6: =I4-I5 -> 109453.48 | ... K6: =K4-K5 -> 140785.02 | L6: =SUM(Quarters!H6:K6) -> 140785.02 | M6: =M4*M24 -> 182461.99 | N6: =N4*N24 -> 145911.25
A7: Other Income | B7: ='Data Sheet'!B25 -> 12905.08 | C7: ='Data Sheet'!C25 -> 16056.6 | D7: ='Data Sheet'!D25 -> 18947.05 | E7: ='Data Sheet'!E25 -> 24878.97 | F7: ='Data Sheet'!F25 -> 27332.88 | G7: ='Data Sheet'!G25 -> 31758.99 | H7: ='Data Sheet'!H25 -> 33912.05 | I7: ='Data Sheet'!I25 -> 124345.75 | ... K7: ='Data Sheet'!K25 -> 146847.66 | L7: =SUM(Quarters!H7:K7) -> 146847.66 | M7: 0 | N7: 0
A8: Depreciation | B8: ='Data Sheet'!B26 -> 886.19 | C8: ='Data Sheet'!C26 -> 966.78 | D8: ='Data Sheet'!D26 -> 1220.67 | E8: ='Data Sheet'!E26 -> 1276.77 | F8: ='Data Sheet'!F26 -> 1385.01 | G8: ='Data Sheet'!G26 -> 1680.73 | H8: ='Data Sheet'!H26 -> 2345.47 | I8: ='Data Sheet'!I26 -> 3092.08 | ... K8: ='Data Sheet'!K26 -> 0 | L8: =SUM(Quarters!H8:K8) -> 0 | M8: =+$L8 -> 0 | N8: =+$L8 -> 0
A9: Interest | B9: ='Data Sheet'!B27 -> 38041.58 | C9: ='Data Sheet'!C27 -> 42381.48 | D9: ='Data Sheet'!D27 -> 53712.69 | E9: ='Data Sheet'!E27 -> 62137.42 | F9: ='Data Sheet'!F27 -> 59247.59 | G9: ='Data Sheet'!G27 -> 58584.33 | H9: ='Data Sheet'!H27 -> 77779.94 | I9: ='Data Sheet'!I27 -> 154138.55 | ... K9: ='Data Sheet'!K27 -> 185491.23 | L9: =SUM(Quarters!H9:K9) -> 185491.23 | M9: =+$L9 -> 185491.23 | N9: =+$L9 -> 185491.23
A10: Profit before tax | B10: ='Data Sheet'!B28 -> 23392.97 | C10: ='Data Sheet'!C28 -> 28463.92 | D10: ='Data Sheet'!D28 -> 34318.16 | E10: ='Data Sheet'!E28 -> 38194.86 | F10: ='Data Sheet'!F28 -> 42796.15 | G10: ='Data Sheet'!G28 -> 50873.38 | H10: ='Data Sheet'!H28 -> 61498.39 | I10: ='Data Sheet'!I28 -> 76568.6 | ... K10: ='Data Sheet'!K28 -> 102141.45 | L10: =SUM(Quarters!H10:K10) -> 102141.45 | M10: =M6+M7-SUM(M8:M9) -> -3029.2447 | N10: =N6+N7-SUM(N8:N9) -> -39579.984
A11: Tax | B11: ='Data Sheet'!B29 -> 8078.12 | C11: ='Data Sheet'!C29 -> 9903.08 | D11: ='Data Sheet'!D29 -> 11872.55 | E11: ='Data Sheet'!E29 -> 10898.59 | F11: ='Data Sheet'!F29 -> 10939.38 | G11: ='Data Sheet'!G29 -> 12722.48 | H11: ='Data Sheet'!H29 -> 15349.69 | I11: ='Data Sheet'!I29 -> 11122.1 | ... K11: ='Data Sheet'!K29 -> 22921.99 | L11: =SUM(Quarters!H11:K11) -> 22921.99 | M11: =IF($L10>0,$L11/$L10,0) -> 0.22441418 | N11: =IF($L10>0,$L11/$L10,0) -> 0.22441418
A12: Net profit | B12: ='Data Sheet'!B30 -> 15280.48 | C12: ='Data Sheet'!C30 -> 18510.02 | D12: ='Data Sheet'!D30 -> 22332.43 | E12: ='Data Sheet'!E30 -> 27253.95 | F12: ='Data Sheet'!F30 -> 31833.21 | G12: ='Data Sheet'!G30 -> 38052.75 | H12: ='Data Sheet'!H30 -> 45997.11 | I12: ='Data Sheet'!I30 -> 64062.04 | ... K12: ='Data Sheet'!K30 -> 76025.97 | L12: =SUM(Quarters!H12:K12) -> 76025.97 | M12: =M10-M11*M10 -> -2349.4392 | N12: =N10-N11*N10 -> -30697.674
A13: EPS | B13: =IF('Data Sheet'!B93>0,B12/'Data Sheet'!B93,0) -> 14.907494 | C13: =IF('Data Sheet'!C93>0,C12/'Data Sheet'!C93,0) -> 17.831702 | D13: =IF('Data Sheet'!D93>0,D12/'Data Sheet'!D93,0) -> 20.501258 | E13: =IF('Data Sheet'!E93>0,E12/'Data Sheet'!E93,0) -> 24.851777 | F13: =IF('Data Sheet'!F93>0,F12/'Data Sheet'!F93,0) -> 28.872089 | G13: =IF('Data Sheet'!G93>0,G12/'Data Sheet'!G93,0) -> 34.309266 | H13: =IF('Data Sheet'!H93>0,H12/'Data Sheet'!H93,0) -> 41.217895 | I13: =IF('Data Sheet'!I93>0,I12/'Data Sheet'!I93,0) -> 42.163277 | ... K13: =IF('Data Sheet'!K93>0,K12/'Data Sheet'!K93,0) -> 49.38868 | L13: =IF('Data Sheet'!$B6>0,'Profit & Loss'!L12/'Data Sheet'!$B6,0) -> 49.375052 | M13: =IF('Data Sheet'!$B6>0,'Profit & Loss'!M12/'Data Sheet'!$B6,0) -> -1.5258428 | N13: =IF('Data Sheet'!$B6>0,'Profit & Loss'!N12/'Data Sheet'!$B6,0) -> -19.936599
A14: Price to earning | B14: =IF(B15>0,B15/B13,"") -> 24.191859 | C14: =IF(C15>0,C15/C13,"") -> 26.443353 | D14: =IF(D15>0,D15/D13,"") -> 28.277777 | E14: =IF(E15>0,E15/E13,"") -> 17.340812 | F14: =IF(F15>0,F15/F13,"") -> 25.866851 | G14: =IF(G15>0,G15/G13,"") -> 21.428031 | H14: =IF(H15>0,H15/H13,"") -> 19.525015 | I14: =IF(I15>0,I15/I13,"") -> 17.170155 | ... K14: =IF(K15>0,K15/K13,"") -> 14.812099 | L14: =IF(L13>0,L15/L13,0) -> 15.007579 | M14: =M25 -> 16.687883 | N14: =N25 -> 15.007579
A15: Price | B15: ='Data Sheet'!B90 -> 360.64 | C15: ='Data Sheet'!C90 -> 471.53 | D15: ='Data Sheet'!D90 -> 579.73 | E15: ='Data Sheet'!E90 -> 430.95 | F15: ='Data Sheet'!F90 -> 746.83 | G15: ='Data Sheet'!G90 -> 735.18 | H15: ='Data Sheet'!H90 -> 804.78 | I15: ='Data Sheet'!I90 -> 723.95 | ... K15: ='Data Sheet'!K90 -> 731.55 | L15: ='Data Sheet'!B8 -> 741 | M15: =M13*M14 -> -25.463087 | N15: =N13*N14 -> -299.20008
A17: RATIOS:
A18: Dividend Payout | B18: =IF('Data Sheet'!B30>0, 'Data Sheet'!B31/'Data Sheet'!B30, 0) -> 0.18447064 | C18: =IF('Data Sheet'!C30>0, 'Data Sheet'!C31/'Data Sheet'!C30, 0) -> 0.18225966 | D18: =IF('Data Sheet'!D30>0, 'Data Sheet'!D31/'Data Sheet'!D30, 0) -> 0.18291561 | E18: =IF('Data Sheet'!E30>0, 'Data Sheet'!E31/'Data Sheet'!E30, 0) -> 0.05029803 | F18: =IF('Data Sheet'!F30>0, 'Data Sheet'!F31/'Data Sheet'!F30, 0) -> 0.11256546 | G18: =IF('Data Sheet'!G30>0, 'Data Sheet'!G31/'Data Sheet'!G30, 0) -> 0.22588433 | H18: =IF('Data Sheet'!H30>0, 'Data Sheet'!H31/'Data Sheet'!H30, 0) -> 0.23048035 | I18: =IF('Data Sheet'!I30>0, 'Data Sheet'!I31/'Data Sheet'!I30, 0) -> 0.23124396 | ... K18: =IF('Data Sheet'!K30>0, 'Data Sheet'!K31/'Data Sheet'!K30, 0) -> 0.3138371
A19: OPM | B19: =IF(B6>0,B6/B4,0) -> 0.67441995 | C19: =IF(C6>0,C6/C4,0) -> 0.65373423 | D19: =IF(D6>0,D6/D4,0) -> 0.66854294 | E19: =IF(E6>0,E6/E4,0) -> 0.62796076 | F19: =IF(F6>0,F6/F4,0) -> 0.59194437 | G19: =IF(G6>0,G6/G4,0) -> 0.58394546 | H19: =IF(H6>0,H6/H4,0) -> 0.63080056 | I19: =IF(I6>0,I6/I4,0) -> 0.38587646 | ... L19: =IF(L6>0,L6/L4,0) -> 0.4038408
G22: TRENDS: | H22: 10 YEARS | I22: 7 YEARS | J22: 5 YEARS | K22: 3 YEARS | L22: RECENT | M22: BEST | N22: WORST
G23: Sales Growth | H23: =IF(B4=0,"",POWER($K4/B4,1/9)-1) -> 0.18923589 | I23: =IF(D4=0,"",POWER($K4/D4,1/7)-1) -> 0.18674139 | J23: =IF(F4=0,"",POWER($K4/F4,1/5)-1) -> 0.22082444 | K23: =IF(H4=0,"",POWER($K4/H4, 1/3)-1) -> 0.26860109 | L23: =IF(ISERROR(MAX(IF(J4=0,"",(K4-J4)/J4),IF(K4=0,"",(L4-K4)/K4))),"",MAX(IF(J4=0,"",(K4-J4)/J4),IF(K4=0,"",(L4-K4)/K4))) -> 0.03641173 | M23: =MAX(K23:L23) -> 0.26860109 | N23: =MIN(H23:L23) -> 0.03641173
G24: OPM | H24: =IF(SUM(B4:$K$4)=0,"",SUMPRODUCT(B19:$K$19,B4:$K$4)/SUM(B4:$K$4)) -> 0.51124857 | I24: =IF(SUM(E4:$K$4)=0,"",SUMPRODUCT(E19:$K$19,E4:$K$4)/SUM(E4:$K$4)) -> 0.48461188 | J24: =IF(SUM(G4:$K$4)=0,"",SUMPRODUCT(G19:$K$19,G4:$K$4)/SUM(G4:$K$4)) -> 0.46005844 | K24: =IF(SUM(I4:$K$4)=0, "", SUMPRODUCT(I19:$K$19,I4:$K$4)/SUM(I4:$K$4)) -> 0.41257324 | L24: =L19 -> 0.4038408 | M24: =MAX(K24:L24) -> 0.41257324 | N24: =MIN(H24:L24) -> 0.4038408
G25: Price to Earning | H25: =IF(ISERROR(AVERAGEIF(B14:$L14,">0")),"",AVERAGEIF(B14:$L14,">0")) -> 20.893203 | I25: =IF(ISERROR(AVERAGEIF(E14:$L14,">0")),"",AVERAGEIF(E14:$L14,">0")) -> 18.86403 | J25: =IF(ISERROR(AVERAGEIF(G14:$L14,">0")),"",AVERAGEIF(G14:$L14,">0")) -> 17.950763 | K25: =IF(ISERROR(AVERAGEIF(I14:$L14,">0")),"",AVERAGEIF(I14:$L14,">0")) -> 16.687883 | L25: =L14 -> 15.007579 | M25: =MAX(K25:L25) -> 16.687883 | N25: =MIN(H25:L25) -> 15.007579

Sheet Quarters
A1: ='Profit & Loss'!A1 -> HDFC BANK LTD | E1: =UPDATE | J1: SCREENER.IN
A3: Narration | B3: ='Data Sheet'!B41 -> 45291 | C3: ='Data Sheet'!C41 -> 45382 | D3: ='Data Sheet'!D41 -> 45473 | E3: ='Data Sheet'!E41 -> 45565 | F3: ='Data Sheet'!F41 -> 45657 | G3: ='Data Sheet'!G41 -> 45747 | H3: ='Data Sheet'!H41 -> 45838 | I3: ='Data Sheet'!I41 -> 45930 | ... K3: ='Data Sheet'!K41 -> 46112
A4: Sales | B4: ='Data Sheet'!B42 -> 78008.17 | C4: ='Data Sheet'!C42 -> 79433.61 | D4: ='Data Sheet'!D42 -> 81546.2 | E4: ='Data Sheet'!E42 -> 83001.72 | F4: ='Data Sheet'!F42 -> 85040.17 | G4: ='Data Sheet'!G42 -> 86779.34 | H4: ='Data Sheet'!H42 -> 87371.87 | I4: ='Data Sheet'!I42 -> 86993.84 | ... K4: ='Data Sheet'!K42 -> 87182.5
A5: Expenses | B5: ='Data Sheet'!B43 -> 50530.03 | C5: ='Data Sheet'!C43 -> 62938.45 | D5: ='Data Sheet'!D43 -> 49689.62 | E5: ='Data Sheet'!E43 -> 52074.11 | F5: ='Data Sheet'!F43 -> 41306.79 | G5: ='Data Sheet'!G43 -> 47709.16 | H5: ='Data Sheet'!H43 -> 64496.63 | I5: ='Data Sheet'!I43 -> 45160.88 | ... K5: ='Data Sheet'!K43 -> 44027.87
A6: Operating Profit | B6: ='Data Sheet'!B50 -> 27478.14 | C6: ='Data Sheet'!C50 -> 16495.16 | D6: ='Data Sheet'!D50 -> 31856.58 | E6: ='Data Sheet'!E50 -> 30927.61 | F6: ='Data Sheet'!F50 -> 43733.38 | G6: ='Data Sheet'!G50 -> 39070.18 | H6: ='Data Sheet'!H50 -> 22875.24 | I6: ='Data Sheet'!I50 -> 41832.96 | ... K6: ='Data Sheet'!K50 -> 43154.63
A7: Other Income | B7: ='Data Sheet'!B44 -> 37007.34 | C7: ='Data Sheet'!C44 -> 44957.74 | D7: ='Data Sheet'!D44 -> 35450.29 | E7: ='Data Sheet'!E44 -> 38455.02 | F7: ='Data Sheet'!F44 -> 27153.77 | G7: ='Data Sheet'!G44 -> 33489.42 | H7: ='Data Sheet'!H44 -> 45683.1 | I7: ='Data Sheet'!I44 -> 31566.79 | ... K7: ='Data Sheet'!K44 -> 29737.44
A8: Depreciation | B8: ='Data Sheet'!B45 -> 0 | C8: ='Data Sheet'!C45 -> 0 | D8: ='Data Sheet'!D45 -> 0 | E8: ='Data Sheet'!E45 -> 0 | F8: ='Data Sheet'!F45 -> 0 | G8: ='Data Sheet'!G45 -> 0 | H8: ='Data Sheet'!H45 -> 0 | I8: ='Data Sheet'!I45 -> 0 | ... K8: ='Data Sheet'!K45 -> 0
A9: Interest | B9: ='Data Sheet'!B46 -> 43242.37 | C9: ='Data Sheet'!C46 -> 43691.51 | D9: ='Data Sheet'!D46 -> 44579.5 | E9: ='Data Sheet'!E46 -> 45414.21 | F9: ='Data Sheet'!F46 -> 46914.28 | G9: ='Data Sheet'!G46 -> 46986.21 | H9: ='Data Sheet'!H46 -> 47708.51 | I9: ='Data Sheet'!I46 -> 46740.86 | ... K9: ='Data Sheet'!K46 -> 45220.44
A10: Profit before tax | B10: ='Data Sheet'!B47 -> 21243.11 | C10: ='Data Sheet'!C47 -> 17761.39 | D10: ='Data Sheet'!D47 -> 22727.37 | E10: ='Data Sheet'!E47 -> 23968.42 | F10: ='Data Sheet'!F47 -> 23972.87 | G10: ='Data Sheet'!G47 -> 25573.39 | H10: ='Data Sheet'!H47 -> 20849.83 | I10: ='Data Sheet'!I47 -> 26658.89 | ... K10: ='Data Sheet'!K47 -> 27671.63
A11: Tax | B11: ='Data Sheet'!B48 -> 3525.11 | C11: ='Data Sheet'!C48 -> -251.48 | D11: ='Data Sheet'!D48 -> 5539.32 | E11: ='Data Sheet'!E48 -> 5340.98 | F11: ='Data Sheet'!F48 -> 5632.76 | G11: ='Data Sheet'!G48 -> 6288.82 | H11: ='Data Sheet'!H48 -> 3759.4 | I11: ='Data Sheet'!I48 -> 6295.12 | ... K11: ='Data Sheet'!K48 -> 6597.41
A12: Net profit | B12: ='Data Sheet'!B49 -> 17257.87 | C12: ='Data Sheet'!C49 -> 17622.38 | D12: ='Data Sheet'!D49 -> 16474.85 | E12: ='Data Sheet'!E49 -> 17825.91 | F12: ='Data Sheet'!F49 -> 17656.61 | G12: ='Data Sheet'!G49 -> 18834.88 | H12: ='Data Sheet'!H49 -> 16257.91 | I12: ='Data Sheet'!I49 -> 19610.67 | ... K12: ='Data Sheet'!K49 -> 20350.76
A14: OPM | B14: =IF(B4>0,B6/B4,"") -> 0.35224695 | C14: =IF(C4>0,C6/C4,"") -> 0.2076597 | D14: =IF(D4>0,D6/D4,"") -> 0.39065683 | E14: =IF(E4>0,E6/E4,"") -> 0.37261409 | F14: =IF(F4>0,F6/F4,"") -> 0.51426732 | G14: =IF(G4>0,G6/G4,"") -> 0.45022444 | H14: =IF(H4>0,H6/H4,"") -> 0.2618147 | I14: =IF(I4>0,I6/I4,"") -> 0.48087267 | ... K14: =IF(K4>0,K6/K4,"") -> 0.49499188

Sheet Balance Sheet
A1: ='Profit & Loss'!A1 -> HDFC BANK LTD | E1: =UPDATE | J1: SCREENER.IN
A3: Narration | B3: ='Data Sheet'!B56 -> 42825 | C3: ='Data Sheet'!C56 -> 43190 | D3: ='Data Sheet'!D56 -> 43555 | E3: ='Data Sheet'!E56 -> 43921 | F3: ='Data Sheet'!F56 -> 44286 | G3: ='Data Sheet'!G56 -> 44651 | H3: ='Data Sheet'!H56 -> 45016 | I3: ='Data Sheet'!I56 -> 45382 | ... K3: ='Data Sheet'!K56 -> 46112
A4: Equity Share Capital | B4: ='Data Sheet'!B57 -> 512.51 | C4: ='Data Sheet'!C57 -> 519.02 | D4: ='Data Sheet'!D57 -> 544.66 | E4: ='Data Sheet'!E57 -> 548.33 | F4: ='Data Sheet'!F57 -> 551.28 | G4: ='Data Sheet'!G57 -> 554.55 | H4: ='Data Sheet'!H57 -> 557.97 | I4: ='Data Sheet'!I57 -> 759.69 | ... K4: ='Data Sheet'!K57 -> 1539.34
A5: Reserves | B5: ='Data Sheet'!B58 -> 91281.44 | C5: ='Data Sheet'!C58 -> 109080.11 | D5: ='Data Sheet'!D58 -> 153128 | E5: ='Data Sheet'!E58 -> 175810.38 | F5: ='Data Sheet'!F58 -> 209258.9 | G5: ='Data Sheet'!G58 -> 246771.62 | H5: ='Data Sheet'!H58 -> 288879.53 | I5: ='Data Sheet'!I58 -> 455635.56 | ... K5: ='Data Sheet'!K58 -> 579975.02
A6: Borrowings | B6: ='Data Sheet'!B59 -> 741549.89 | C6: ='Data Sheet'!C59 -> 944817.22 | D6: ='Data Sheet'!D59 -> 1080235.5 | E6: ='Data Sheet'!E59 -> 1333041.4 | F6: ='Data Sheet'!F59 -> 1511417.6 | G6: ='Data Sheet'!G59 -> 1784969.5 | H6: ='Data Sheet'!H59 -> 2139211.9 | I6: ='Data Sheet'!I59 -> 3107502.7 | ... K6: ='Data Sheet'!K59 -> 3688122.8
A7: Other Liabilities | B7: ='Data Sheet'!B60 -> 59000.32 | C7: ='Data Sheet'!C60 -> 48769.82 | D7: ='Data Sheet'!D60 -> 58897.59 | E7: ='Data Sheet'!E60 -> 71430.27 | F7: ='Data Sheet'!F60 -> 78278.83 | G7: ='Data Sheet'!G60 -> 90638.6 | H7: ='Data Sheet'!H60 -> 101783.03 | I7: ='Data Sheet'!I60 -> 466296.27 | ... K7: ='Data Sheet'!K60 -> 638403.64
A8: Total | B8: ='Data Sheet'!B61 -> 892344.16 | C8: ='Data Sheet'!C61 -> 1103186.2 | D8: ='Data Sheet'!D61 -> 1292805.7 | E8: ='Data Sheet'!E61 -> 1580830.4 | F8: ='Data Sheet'!F61 -> 1799506.6 | G8: ='Data Sheet'!G61 -> 2122934.3 | H8: ='Data Sheet'!H61 -> 2530432.4 | I8: ='Data Sheet'!I61 -> 4030194.3 | ... K8: ='Data Sheet'!K61 -> 4908040.8
A10: Net Block | B10: ='Data Sheet'!B62 -> 3999.7 | C10: ='Data Sheet'!C62 -> 4008.13 | D10: ='Data Sheet'!D62 -> 4368.63 | E10: ='Data Sheet'!E62 -> 4775.65 | F10: ='Data Sheet'!F62 -> 5248.35 | G10: ='Data Sheet'!G62 -> 6432.07 | H10: ='Data Sheet'!H62 -> 8431.35 | I10: ='Data Sheet'!I62 -> 12603.76 | ... K10: ='Data Sheet'!K62 -> 16491.59
A11: Capital Work in Progress | B11: ='Data Sheet'!B63 -> 0 | C11: ='Data Sheet'!C63 -> 0 | D11: ='Data Sheet'!D63 -> 0 | E11: ='Data Sheet'!E63 -> 0 | F11: ='Data Sheet'!F63 -> 0 | G11: ='Data Sheet'!G63 -> 0 | H11: ='Data Sheet'!H63 -> 0 | I11: ='Data Sheet'!I63 -> 0 | ... K11: ='Data Sheet'!K63 -> 0
A12: Investments | B12: ='Data Sheet'!B64 -> 210777.11 | C12: ='Data Sheet'!C64 -> 238460.92 | D12: ='Data Sheet'!D64 -> 289445.87 | E12: ='Data Sheet'!E64 -> 389304.95 | F12: ='Data Sheet'!F64 -> 438823.11 | G12: ='Data Sheet'!G64 -> 449263.86 | H12: ='Data Sheet'!H64 -> 511581.71 | I12: ='Data Sheet'!I64 -> 1005681.6 | ... K12: ='Data Sheet'!K64 -> 1280216.3
A13: Other Assets | B13: ='Data Sheet'!B65 -> 677567.35 | C13: ='Data Sheet'!C65 -> 860717.12 | D13: ='Data Sheet'!D65 -> 998991.21 | E13: ='Data Sheet'!E65 -> 1186749.8 | F13: ='Data Sheet'!F65 -> 1355435.2 | G13: ='Data Sheet'!G65 -> 1667238.4 | H13: ='Data Sheet'!H65 -> 2010419.4 | I13: ='Data Sheet'!I65 -> 3011908.9 | ... K13: ='Data Sheet'!K65 -> 3611333
A14: Total | B14: ='Data Sheet'!B66 -> 892344.16 | C14: ='Data Sheet'!C66 -> 1103186.2 | D14: ='Data Sheet'!D66 -> 1292805.7 | E14: ='Data Sheet'!E66 -> 1580830.4 | F14: ='Data Sheet'!F66 -> 1799506.6 | G14: ='Data Sheet'!G66 -> 2122934.3 | H14: ='Data Sheet'!H66 -> 2530432.4 | I14: ='Data Sheet'!I66 -> 4030194.3 | ... K14: ='Data Sheet'!K66 -> 4908040.8
A16: Working Capital | B16: =B13-B7 -> 618567.03 | C16: =C13-C7 -> 811947.3 | D16: =D13-D7 -> 940093.62 | E16: =E13-E7 -> 1115319.6 | F16: =F13-F7 -> 1277156.3 | G16: =G13-G7 -> 1576599.8 | H16: =H13-H7 -> 1908636.3 | I16: =I13-I7 -> 2545612.6 | ... K16: =K13-K7 -> 2972929.3
A17: Debtors | B17: ='Data Sheet'!B67 -> 0 | C17: ='Data Sheet'!C67 -> 0 | D17: ='Data Sheet'!D67 -> 0 | E17: ='Data Sheet'!E67 -> 0 | F17: ='Data Sheet'!F67 -> 0 | G17: ='Data Sheet'!G67 -> 0 | H17: ='Data Sheet'!H67 -> 0 | I17: ='Data Sheet'!I67 -> 0 | ... K17: ='Data Sheet'!K67 -> 0
A18: Inventory | B18: ='Data Sheet'!B68 -> 0 | C18: ='Data Sheet'!C68 -> 0 | D18: ='Data Sheet'!D68 -> 0 | E18: ='Data Sheet'!E68 -> 0 | F18: ='Data Sheet'!F68 -> 0 | G18: ='Data Sheet'!G68 -> 0 | H18: ='Data Sheet'!H68 -> 0 | I18: ='Data Sheet'!I68 -> 0 | ... K18: ='Data Sheet'!K68 -> 0
A20: Debtor Days | B20: =IF('Profit & Loss'!B4>0,'Balance Sheet'!B17/('Profit & Loss'!B4/365),0) -> 0 | C20: =IF('Profit & Loss'!C4>0,'Balance Sheet'!C17/('Profit & Loss'!C4/365),0) -> 0 | D20: =IF('Profit & Loss'!D4>0,'Balance Sheet'!D17/('Profit & Loss'!D4/365),0) -> 0 | E20: =IF('Profit & Loss'!E4>0,'Balance Sheet'!E17/('Profit & Loss'!E4/365),0) -> 0 | F20: =IF('Profit & Loss'!F4>0,'Balance Sheet'!F17/('Profit & Loss'!F4/365),0) -> 0 | G20: =IF('Profit & Loss'!G4>0,'Balance Sheet'!G17/('Profit & Loss'!G4/365),0) -> 0 | H20: =IF('Profit & Loss'!H4>0,'Balance Sheet'!H17/('Profit & Loss'!H4/365),0) -> 0 | I20: =IF('Profit & Loss'!I4>0,'Balance Sheet'!I17/('Profit & Loss'!I4/365),0) -> 0 | ... K20: =IF('Profit & Loss'!K4>0,'Balance Sheet'!K17/('Profit & Loss'!K4/365),0) -> 0
A21: Inventory Turnover | B21: =IF('Balance Sheet'!B18>0,'Profit & Loss'!B4/'Balance Sheet'!B18,0) -> 0 | C21: =IF('Balance Sheet'!C18>0,'Profit & Loss'!C4/'Balance Sheet'!C18,0) -> 0 | D21: =IF('Balance Sheet'!D18>0,'Profit & Loss'!D4/'Balance Sheet'!D18,0) -> 0 | E21: =IF('Balance Sheet'!E18>0,'Profit & Loss'!E4/'Balance Sheet'!E18,0) -> 0 | F21: =IF('Balance Sheet'!F18>0,'Profit & Loss'!F4/'Balance Sheet'!F18,0) -> 0 | G21: =IF('Balance Sheet'!G18>0,'Profit & Loss'!G4/'Balance Sheet'!G18,0) -> 0 | H21: =IF('Balance Sheet'!H18>0,'Profit & Loss'!H4/'Balance Sheet'!H18,0) -> 0 | I21: =IF('Balance Sheet'!I18>0,'Profit & Loss'!I4/'Balance Sheet'!I18,0) -> 0 | ... K21: =IF('Balance Sheet'!K18>0,'Profit & Loss'!K4/'Balance Sheet'!K18,0) -> 0
A23: Return on Equity | B23: =IF(SUM('Balance Sheet'!B4:B5)>0,'Profit & Loss'!B12/SUM('Balance Sheet'!B4:B5),"") -> 0.166465 | C23: =IF(SUM('Balance Sheet'!C4:C5)>0,'Profit & Loss'!C12/SUM('Balance Sheet'!C4:C5),"") -> 0.16888838 | D23: =IF(SUM('Balance Sheet'!D4:D5)>0,'Profit & Loss'!D12/SUM('Balance Sheet'!D4:D5),"") -> 0.14532468 | E23: =IF(SUM('Balance Sheet'!E4:E5)>0,'Profit & Loss'!E12/SUM('Balance Sheet'!E4:E5),"") -> 0.15453702 | F23: =IF(SUM('Balance Sheet'!F4:F5)>0,'Profit & Loss'!F12/SUM('Balance Sheet'!F4:F5),"") -> 0.15172386 | G23: =IF(SUM('Balance Sheet'!G4:G5)>0,'Profit & Loss'!G12/SUM('Balance Sheet'!G4:G5),"") -> 0.15385654 | H23: =IF(SUM('Balance Sheet'!H4:H5)>0,'Profit & Loss'!H12/SUM('Balance Sheet'!H4:H5),"") -> 0.15891897 | I23: =IF(SUM('Balance Sheet'!I4:I5)>0,'Profit & Loss'!I12/SUM('Balance Sheet'!I4:I5),"") -> 0.14036526 | ... K23: =IF(SUM('Balance Sheet'!K4:K5)>0,'Profit & Loss'!K12/SUM('Balance Sheet'!K4:K5),"") -> 0.13073791
A24: Return on Capital Emp | C24: =IF((B4+B5+B6+C4+C5+C6)>0,('Profit & Loss'!C10+'Profit & Loss'!C9)*2/(B4+B5+B6+C4+C5+C6),"") -> 0.075057627 | D24: =IF((C4+C5+C6+D4+D5+D6)>0,('Profit & Loss'!D10+'Profit & Loss'!D9)*2/(C4+C5+C6+D4+D5+D6),"") -> 0.076939133 | E24: =IF((D4+D5+D6+E4+E5+E6)>0,('Profit & Loss'!E10+'Profit & Loss'!E9)*2/(D4+D5+D6+E4+E5+E6),"") -> 0.073146923 | F24: =IF((E4+E5+E6+F4+F5+F6)>0,('Profit & Loss'!F10+'Profit & Loss'!F9)*2/(E4+E5+E6+F4+F5+F6),"") -> 0.063172697 | G24: =IF((F4+F5+F6+G4+G5+G6)>0,('Profit & Loss'!G10+'Profit & Loss'!G9)*2/(F4+F5+F6+G4+G5+G6),"") -> 0.058322645 | H24: =IF((G4+G5+G6+H4+H5+H6)>0,('Profit & Loss'!H10+'Profit & Loss'!H9)*2/(G4+G5+G6+H4+H5+H6),"") -> 0.062443418 | I24: =IF((H4+H5+H6+I4+I5+I6)>0,('Profit & Loss'!I10+'Profit & Loss'!I9)*2/(H4+H5+H6+I4+I5+I6),"") -> 0.076998023 | J24: =IF((I4+I5+I6+J4+J5+J6)>0,('Profit & Loss'!J10+'Profit & Loss'!J9)*2/(I4+I5+I6+J4+J5+J6),"") -> 0.075394709 | K24: =IF((J4+J5+J6+K4+K5+K6)>0,('Profit & Loss'!K10+'Profit & Loss'!K9)*2/(J4+J5+J6+K4+K5+K6),"") -> 0.070698081

Sheet Cash Flow
A1: ='Balance Sheet'!A1 -> HDFC BANK LTD | E1: =UPDATE | J1: SCREENER.IN
A3: Narration | B3: ='Data Sheet'!B81 -> 42825 | C3: ='Data Sheet'!C81 -> 43190 | D3: ='Data Sheet'!D81 -> 43555 | E3: ='Data Sheet'!E81 -> 43921 | F3: ='Data Sheet'!F81 -> 44286 | G3: ='Data Sheet'!G81 -> 44651 | H3: ='Data Sheet'!H81 -> 45016 | I3: ='Data Sheet'!I81 -> 45382 | ... K3: ='Data Sheet'!K81 -> 46112
A4: Cash from Operating Activity | B4: ='Data Sheet'!B82 -> 17281.59 | C4: ='Data Sheet'!C82 -> 17214.38 | D4: ='Data Sheet'!D82 -> -62871.54 | E4: ='Data Sheet'!E82 -> -16869.09 | F4: ='Data Sheet'!F82 -> 42476.45 | G4: ='Data Sheet'!G82 -> -11959.57 | H4: ='Data Sheet'!H82 -> 20813.7 | I4: ='Data Sheet'!I82 -> 19069.34 | ... K4: ='Data Sheet'!K82 -> 113506.38
A5: Cash from Investing Activity | B5: ='Data Sheet'!B83 -> -1146.38 | C5: ='Data Sheet'!C83 -> -841.6 | D5: ='Data Sheet'!D83 -> -1503.06 | E5: ='Data Sheet'!E83 -> -1402.94 | F5: ='Data Sheet'!F83 -> -1822.7 | G5: ='Data Sheet'!G83 -> -2051.23 | H5: ='Data Sheet'!H83 -> -2992.18 | I5: ='Data Sheet'!I83 -> 16600.42 | ... K5: ='Data Sheet'!K83 -> 6362.72
A6: Cash from Financing Activity | B6: ='Data Sheet'!B84 -> -5892.97 | C6: ='Data Sheet'!C84 -> 57377.66 | D6: ='Data Sheet'!D84 -> 23130.69 | E6: ='Data Sheet'!E84 -> 24394.5 | F6: ='Data Sheet'!F84 -> -7321.35 | G6: ='Data Sheet'!G84 -> 48124.02 | H6: ='Data Sheet'!H84 -> 23940.56 | I6: ='Data Sheet'!I84 -> -3983.06 | ... K6: ='Data Sheet'!K84 -> -59004.85
A7: Net Cash Flow | B7: ='Data Sheet'!B85 -> 10242.24 | C7: ='Data Sheet'!C85 -> 73750.44 | D7: ='Data Sheet'!D85 -> -41243.91 | E7: ='Data Sheet'!E85 -> 6122.47 | F7: ='Data Sheet'!F85 -> 33332.4 | G7: ='Data Sheet'!G85 -> 34113.22 | H7: ='Data Sheet'!H85 -> 41762.08 | I7: ='Data Sheet'!I85 -> 31686.7 | ... K7: ='Data Sheet'!K85 -> 60864.25

Sheet Customization
A1: How to use it?
A3: You can customize this workbook as you want.
B4: You can add custom formating, add conditional formating, add your own formulas… do ANYTHING.
B5: Please don't edit the "Data Sheet" only.
A7: After customization, you can upload this back on Screener.
B8: Upload on: | C8: https://www.screener.in/excel/
A10: Download your customized workbooks now onwards.
B11: Now whenever you will "Export to excel" from Screener, it will export your customized file.
A14: TESTING:
B15: This is a testing feature currently.
B16: You can report any formula errors on the worksheet at: support@screener.in

Sheet Index
B2: ='Data Sheet'!B1 -> HDFC BANK LTD
B4: Equity Research & Valuation Model
B6: Prepared by: | D6: Ashish Jha
D7: NIT Surat | L7: Metric | N7: Value
B9: Company: | D9: ='Data Sheet'!B1 -> HDFC BANK LTD | L9: CMP | N9: ="₹"&TEXT('Excess Return Val'!D37, "#,##0.0") -> ₹745.0
B10: Sector: | D10: Banking & Financial Services (Private Sector)
B11: Currency: | D11: INR (₹) | L11: Excess Return Value | N11: ="₹"&TEXT('Excess Return Val'!D35, "#,##0.0") -> ₹372.9
B12: Valuation Date: | D12: =TODAY() -> 46208
L13: View
A14: # | B14: Index
L15: Recommendation
D16: Investment Summary
D18: Data Sheet
D20: Historical Financial Statement
D22: Raw Financial Data
D24: Regression Beta
D26: Cost of Equity
D28: Return on Markets
D30: Equity Forecasting
D32: Excess Returns Valuation
A34: # | B34: Model Flow
D36: Stage | F36: Purpose
D38: Data Collection | E38: Gather historical financial and market data.
D41: Ratio Analysis | E41: Analyze trends, profitability and efficiency.
D44: Forecasting | E44: Estimate future value of equity.
D47: Excess Return Valuation | E47: Determine value of equity.
D50: Investment Conclusion | E50: Form Investment view.
B52: Source: Screener, Yahoo Finance, Company Annual Reports, Aswath Damodaran reports

Sheet Investment Summary
B2: ='Data Sheet'!B1 -> HDFC BANK LTD
B4: Equity Research & Valuation Model
A6: # | B6: Company Overview
B8: CMP | D8: =Index!N9 -> ₹745.0
B10: Excess Return Value | D10: =Index!N11 -> ₹372.9
A12: # | B12: Excess Return Valuation Summary

Sheet Data Sheet
A1: COMPANY NAME | B1: HDFC BANK LTD | E1: =IF(B2<>B3, "A NEW VERSION OF THE WORKSHEET IS AVAILABLE", "")
A2: LATEST VERSION | B2: 2.1 | E2: PLEASE DO NOT MAKE ANY CHANGES TO THIS SHEET
A3: CURRENT VERSION | B3: 2.1
A5: META
A6: Number of shares | B6: =IF(B9>0, B9/B8, 0) -> 1539.7649
A7: Face Value | B7: 1
A8: Current Price | B8: 741
A9: Market Capitalization | B9: 1140965.8
A15: PROFIT & LOSS
A16: Report Date | B16: 42825 | C16: 43190 | D16: 43555 | E16: 43921 | F16: 44286 | G16: 44651 | H16: 45016 | I16: 45382 | J16: 45747 | K16: 46112
A17: Sales | B17: 73271.35 | C17: 85287.84 | D17: 105160.74 | E17: 122189.29 | F17: 128552.4 | G17: 135936.41 | H17: 170754.05 | I17: 283649.02 | J17: 336367.43 | K17: 348615.15
A18: Raw Material Cost
A19: Change in Inventory
A20: Power and Fuel
A21: Other Mfr. Exp | B21: 1271.8 | C21: 1314.97 | D21: 1283.53 | E21: 1293.44 | F21: 1649.11 | G21: 1772.27 | H21: 2176.5 | I21: 3255.75 | J21: 3943.56
A22: Employee Cost | B22: 8508.22 | C22: 9197.15 | D22: 10454.75 | E22: 12924.1 | F22: 13682.35 | G22: 15904.81 | H22: 20031.36 | I22: 31050.07 | J22: 34167.89 | K22: 37604.81
A23: Selling and admin | B23: 3328.39 | C23: 3658.43 | D23: 3900.17 | E23: 4192.15 | F23: 4780.54 | G23: 5406.79 | H23: 6580 | I23: 87580.05 | J23: 105188.45
A24: Other Expenses | B24: 10747.28 | C24: 15361.71 | D24: 19217.82 | E24: 27049.52 | F24: 32344.53 | G24: 33473.09 | H24: 34254.44 | I24: 52309.67 | J24: 43674.55 | K24: 170225.32
A25: Other Income | B25: 12905.08 | C25: 16056.6 | D25: 18947.05 | E25: 24878.97 | F25: 27332.88 | G25: 31758.99 | H25: 33912.05 | I25: 124345.75 | J25: 134548.5 | K25: 146847.66
A26: Depreciation | B26: 886.19 | C26: 966.78 | D26: 1220.67 | E26: 1276.77 | F26: 1385.01 | G26: 1680.73 | H26: 2345.47 | I26: 3092.08 | J26: 3805.23
A27: Interest | B27: 38041.58 | C27: 42381.48 | D27: 53712.69 | E27: 62137.42 | F27: 59247.59 | G27: 58584.33 | H27: 77779.94 | I27: 154138.55 | J27: 183894.2 | K27: 185491.23
A28: Profit before tax | B28: 23392.97 | C28: 28463.92 | D28: 34318.16 | E28: 38194.86 | F28: 42796.15 | G28: 50873.38 | H28: 61498.39 | I28: 76568.6 | J28: 96242.05 | K28: 102141.45
A29: Tax | B29: 8078.12 | C29: 9903.08 | D29: 11872.55 | E29: 10898.59 | F29: 10939.38 | G29: 12722.48 | H29: 15349.69 | I29: 11122.1 | J29: 22801.88 | K29: 22921.99
A30: Net profit | B30: 15280.48 | C30: 18510.02 | D30: 22332.43 | E30: 27253.95 | F30: 31833.21 | G30: 38052.75 | H30: 45997.11 | I30: 64062.04 | J30: 70792.25 | K30: 76025.97
A31: Dividend Amount | B31: 2818.8 | C31: 3373.63 | D31: 4084.95 | E31: 1370.82 | F31: 3583.32 | G31: 8595.52 | H31: 10601.43 | I31: 14813.96 | J31: 16834.84 | K31: 23859.77
A40: Quarters
A41: Report Date | B41: 45291 | C41: 45382 | D41: 45473 | E41: 45565 | F41: 45657 | G41: 45747 | H41: 45838 | I41: 45930 | J41: 46022 | K41: 46112
A42: Sales | B42: 78008.17 | C42: 79433.61 | D42: 81546.2 | E42: 83001.72 | F42: 85040.17 | G42: 86779.34 | H42: 87371.87 | I42: 86993.84 | J42: 87066.94 | K42: 87182.5
A43: Expenses | B43: 50530.03 | C43: 62938.45 | D43: 49689.62 | E43: 52074.11 | F43: 41306.79 | G43: 47709.16 | H43: 64496.63 | I43: 45160.88 | J43: 54144.75 | K43: 44027.87
A44: Other Income | B44: 37007.34 | C44: 44957.74 | D44: 35450.29 | E44: 38455.02 | F44: 27153.77 | G44: 33489.42 | H44: 45683.1 | I44: 31566.79 | J44: 39860.33 | K44: 29737.44
A45: Depreciation
A46: Interest | B46: 43242.37 | C46: 43691.51 | D46: 44579.5 | E46: 45414.21 | F46: 46914.28 | G46: 46986.21 | H46: 47708.51 | I46: 46740.86 | J46: 45821.42 | K46: 45220.44
A47: Profit before tax | B47: 21243.11 | C47: 17761.39 | D47: 22727.37 | E47: 23968.42 | F47: 23972.87 | G47: 25573.39 | H47: 20849.83 | I47: 26658.89 | J47: 26961.1 | K47: 27671.63
A48: Tax | B48: 3525.11 | C48: -251.48 | D48: 5539.32 | E48: 5340.98 | F48: 5632.76 | G48: 6288.82 | H48: 3759.4 | I48: 6295.12 | J48: 6270.06 | K48: 6597.41
A49: Net profit | B49: 17257.87 | C49: 17622.38 | D49: 16474.85 | E49: 17825.91 | F49: 17656.61 | G49: 18834.88 | H49: 16257.91 | I49: 19610.67 | J49: 19806.63 | K49: 20350.76
A50: Operating Profit | B50: 27478.14 | C50: 16495.16 | D50: 31856.58 | E50: 30927.61 | F50: 43733.38 | G50: 39070.18 | H50: 22875.24 | I50: 41832.96 | J50: 32922.19 | K50: 43154.63
A55: BALANCE SHEET
A56: Report Date | B56: 42825 | C56: 43190 | D56: 43555 | E56: 43921 | F56: 44286 | G56: 44651 | H56: 45016 | I56: 45382 | J56: 45747 | K56: 46112
A57: Equity Share Capital | B57: 512.51 | C57: 519.02 | D57: 544.66 | E57: 548.33 | F57: 551.28 | G57: 554.55 | H57: 557.97 | I57: 759.69 | J57: 765.22 | K57: 1539.34
A58: Reserves | B58: 91281.44 | C58: 109080.11 | D58: 153128 | E58: 175810.38 | F58: 209258.9 | G58: 246771.62 | H58: 288879.53 | I58: 455635.56 | J58: 521024.17 | K58: 579975.02
...

Sheet HistoricalFS
B2: ="Historical Financial Statements - "&'Data Sheet'!B1 -> Historical Financial Statements - HDFC BANK LTD
B3: Years | C3: ='Data Sheet'!B16 -> 42825 | D3: ='Data Sheet'!C16 -> 43190 | E3: ='Data Sheet'!D16 -> 43555 | F3: ='Data Sheet'!E16 -> 43921 | G3: ='Data Sheet'!F16 -> 44286 | H3: ='Data Sheet'!G16 -> 44651 | I3: ='Data Sheet'!H16 -> 45016 | J3: ='Data Sheet'!I16 -> 45382 | ... L3: ='Data Sheet'!K16 -> 46112 | M3: LTM
A5: # | B5: Income Statement
B6: Sales | C6: =IFERROR('Data Sheet'!B17,0) -> 73271.35 | D6: =IFERROR('Data Sheet'!C17,0) -> 85287.84 | E6: =IFERROR('Data Sheet'!D17,0) -> 105160.74 | F6: =IFERROR('Data Sheet'!E17,0) -> 122189.29 | G6: =IFERROR('Data Sheet'!F17,0) -> 128552.4 | H6: =IFERROR('Data Sheet'!G17,0) -> 135936.41 | I6: =IFERROR('Data Sheet'!H17,0) -> 170754.05 | J6: =IFERROR('Data Sheet'!I17,0) -> 283649.02 | ... L6: =IFERROR('Data Sheet'!K17,0) -> 348615.15 | M6: =IFERROR(SUM('Data Sheet'!H42:K42), 0) -> 348615.15
B7: Sales Growth | C7: - | D7: =D6/C6-1 -> 0.16399984 | E7: =E6/D6-1 -> 0.23300977 | F7: =F6/E6-1 -> 0.16192878 | G7: =G6/F6-1 -> 0.052075841 | H7: =H6/G6-1 -> 0.05743969 | I7: =I6/H6-1 -> 0.25613182 | J7: =J6/I6-1 -> 0.66115545 | K7: =K6/J6-1 -> 0.1858579 | ... M7: =M6/L6-1 -> 0
B9: COGS | C9: =IFERROR(SUM('Data Sheet'!B18,'Data Sheet'!B20:B21)-1*('Data Sheet'!B19), 0) -> 1271.8 | D9: =IFERROR(SUM('Data Sheet'!C18,'Data Sheet'!C20:C21)-1*('Data Sheet'!C19), 0) -> 1314.97 | E9: =IFERROR(SUM('Data Sheet'!D18,'Data Sheet'!D20:D21)-1*('Data Sheet'!D19), 0) -> 1283.53 | F9: =IFERROR(SUM('Data Sheet'!E18,'Data Sheet'!E20:E21)-1*('Data Sheet'!E19), 0) -> 1293.44 | G9: =IFERROR(SUM('Data Sheet'!F18,'Data Sheet'!F20:F21)-1*('Data Sheet'!F19), 0) -> 1649.11 | H9: =IFERROR(SUM('Data Sheet'!G18,'Data Sheet'!G20:G21)-1*('Data Sheet'!G19), 0) -> 1772.27 | I9: =IFERROR(SUM('Data Sheet'!H18,'Data Sheet'!H20:H21)-1*('Data Sheet'!H19), 0) -> 2176.5 | J9: =IFERROR(SUM('Data Sheet'!I18,'Data Sheet'!I20:I21)-1*('Data Sheet'!I19), 0) -> 3255.75 | ... L9: =IFERROR(SUM('Data Sheet'!K18,'Data Sheet'!K20:K21)-1*('Data Sheet'!K19), 0) -> 0 | M9: =IFERROR(SUM('Data Sheet'!H43:K43), 0) -> 207830.13
B10: COGS % Sales | C10: =C9/C6 -> 0.017357398 | D10: =D9/D6 -> 0.015418024 | E10: =E9/E6 -> 0.01220541 | F10: =F9/F6 -> 0.010585543 | G10: =G9/G6 -> 0.01282831 | H10: =H9/H6 -> 0.013037493 | I10: =I9/I6 -> 0.012746403 | J10: =J9/J6 -> 0.011478094 | ... M10: =M9/M6 -> 0.5961592
B12: Gross Profit | C12: =C6-C9 -> 71999.55 | D12: =D6-D9 -> 83972.87 | E12: =E6-E9 -> 103877.21 | F12: =F6-F9 -> 120895.85 | G12: =G6-G9 -> 126903.29 | H12: =H6-H9 -> 134164.14 | I12: =I6-I9 -> 168577.55 | J12: =J6-J9 -> 280393.27 | ... M12: =M6-M9 -> 140785.02
B13: Gross Margins | C13: =C12/C6 -> 0.9826426 | D13: =D12/D6 -> 0.98458198 | E13: =E12/E6 -> 0.98779459 | F13: =F12/F6 -> 0.98941446 | G13: =G12/G6 -> 0.98717169 | H13: =H12/H6 -> 0.98696251 | I13: =I12/I6 -> 0.9872536 | J13: =J12/J6 -> 0.98852191 | ... M13: =M12/M6 -> 0.4038408
B15: Selling & General Expenses | C15: =IFERROR(SUM('Data Sheet'!B23:B24), 0) -> 14075.67 | D15: =IFERROR(SUM('Data Sheet'!C23:C24), 0) -> 19020.14 | E15: =IFERROR(SUM('Data Sheet'!D23:D24), 0) -> 23117.99 | F15: =IFERROR(SUM('Data Sheet'!E23:E24), 0) -> 31241.67 | G15: =IFERROR(SUM('Data Sheet'!F23:F24), 0) -> 37125.07 | H15: =IFERROR(SUM('Data Sheet'!G23:G24), 0) -> 38879.88 | I15: =IFERROR(SUM('Data Sheet'!H23:H24), 0) -> 40834.44 | J15: =IFERROR(SUM('Data Sheet'!I23:I24), 0) -> 139889.72 | ... L15: =IFERROR(SUM('Data Sheet'!K23:K24), 0) -> 170225.32 | M15: -
B16: S&G Exp % Sales | C16: =C15/C6 -> 0.19210333 | D16: =D15/D6 -> 0.22301116 | E16: =E15/E6 -> 0.2198348 | F16: =F15/F6 -> 0.25568256 | G16: =G15/G6 -> 0.28879329 | H16: =H15/H6 -> 0.2860152 | I16: =I15/I6 -> 0.23914185 | J16: =J15/J6 -> 0.49317893 | ... L16: =L15/L6 -> 0.48829008 | M16: 0
B18: EBITDA | C18: =C12-C15 -> 57923.88 | D18: =D12-D15 -> 64952.73 | E18: =E12-E15 -> 80759.22 | F18: =F12-F15 -> 89654.18 | G18: =G12-G15 -> 89778.22 | H18: =H12-H15 -> 95284.26 | I18: =I12-I15 -> 127743.11 | J18: =J12-J15 -> 140503.55 | ... L18: =L12-L15 -> 178389.83 | M18: =IFERROR(SUM('Data Sheet'!H50:K50, 'Data Sheet'!H45:K45), 0) -> 140785.02
B19: EBITDA Margins | C19: =C18/C6 -> 0.79053928 | D19: =D18/D6 -> 0.76157082 | E19: =E18/E6 -> 0.76795979 | F19: =F18/F6 -> 0.7337319 | G19: =G18/G6 -> 0.6983784 | H19: =H18/H6 -> 0.7009473 | I19: =I18/I6 -> 0.74811174 | J19: =J18/J6 -> 0.49534298 | ... M19: =M18/M6 -> 0.4038408
B21: Interest | C21: =IFERROR('Data Sheet'!B27, 0) -> 38041.58 | D21: =IFERROR('Data Sheet'!C27, 0) -> 42381.48 | E21: =IFERROR('Data Sheet'!D27, 0) -> 53712.69 | F21: =IFERROR('Data Sheet'!E27, 0) -> 62137.42 | G21: =IFERROR('Data Sheet'!F27, 0) -> 59247.59 | H21: =IFERROR('Data Sheet'!G27, 0) -> 58584.33 | I21: =IFERROR('Data Sheet'!H27, 0) -> 77779.94 | J21: =IFERROR('Data Sheet'!I27, 0) -> 154138.55 | ... L21: =IFERROR('Data Sheet'!K27, 0) -> 185491.23 | M21: =IFERROR(SUM('Data Sheet'!H46:K46), 0) -> 185491.23
B22: Interest % Sales | C22: =C21/C6 -> 0.51918765 | D22: =D21/D6 -> 0.49692289 | E22: =E21/E6 -> 0.51076752 | F22: =F21/F6 -> 0.50853409 | G22: =G21/G6 -> 0.4608828 | H22: =H21/H6 -> 0.43096864 | I22: =I21/I6 -> 0.45550861 | J22: =J21/J6 -> 0.54341295 | ... M22: =M21/M6 -> 0.53208023
B24: Depreciation | C24: =IFERROR('Data Sheet'!B26, 0) -> 886.19 | D24: =IFERROR('Data Sheet'!C26, 0) -> 966.78 | E24: =IFERROR('Data Sheet'!D26, 0) -> 1220.67 | F24: =IFERROR('Data Sheet'!E26, 0) -> 1276.77 | G24: =IFERROR('Data Sheet'!F26, 0) -> 1385.01 | H24: =IFERROR('Data Sheet'!G26, 0) -> 1680.73 | I24: =IFERROR('Data Sheet'!H26, 0) -> 2345.47 | J24: =IFERROR('Data Sheet'!I26, 0) -> 3092.08 | ... L24: =IFERROR('Data Sheet'!K26, 0) -> 0 | M24: =IFERROR(SUM('Data Sheet'!H45:K45), 0) -> 0
B25: Depreciation % Sales | C25: =C24/C6 -> 0.012094632 | D25: =D24/D6 -> 0.011335496 | E25: =E24/E6 -> 0.011607659 | F25: =F24/F6 -> 0.010449115 | G25: =G24/G6 -> 0.010773895 | H25: =H24/H6 -> 0.01236409 | I25: =I24/I6 -> 0.013735955 | J25: =J24/J6 -> 0.010901078 | ... M25: =M24/M6 -> 0
B27: Earnings Before Tax | C27: ='Data Sheet'!B28 -> 23392.97 | D27: ='Data Sheet'!C28 -> 28463.92 | E27: ='Data Sheet'!D28 -> 34318.16 | F27: ='Data Sheet'!E28 -> 38194.86 | G27: ='Data Sheet'!F28 -> 42796.15 | H27: ='Data Sheet'!G28 -> 50873.38 | I27: ='Data Sheet'!H28 -> 61498.39 | J27: ='Data Sheet'!I28 -> 76568.6 | ... M27: ='Data Sheet'!L28 -> 0
B28: EBT % Sales | C28: =C27/C6 -> 0.3192649 | D28: =D27/D6 -> 0.33373949 | E28: =E27/E6 -> 0.32634004 | F28: =F27/F6 -> 0.31258763 | G28: =G27/G6 -> 0.33290821 | H28: =H27/H6 -> 0.37424396 | I28: =I27/I6 -> 0.36015772 | J28: =J27/J6 -> 0.26994135 | ... M28: =M27/M6 -> 0
B30: Tax | C30: =IFERROR('Data Sheet'!B29, 0) -> 8078.12 | D30: =IFERROR('Data Sheet'!C29, 0) -> 9903.08 | E30: =IFERROR('Data Sheet'!D29, 0) -> 11872.55 | F30: =IFERROR('Data Sheet'!E29, 0) -> 10898.59 | G30: =IFERROR('Data Sheet'!F29, 0) -> 10939.38 | H30: =IFERROR('Data Sheet'!G29, 0) -> 12722.48 | I30: =IFERROR('Data Sheet'!H29, 0) -> 15349.69 | J30: =IFERROR('Data Sheet'!I29, 0) -> 11122.1 | ... L30: =IFERROR('Data Sheet'!K29, 0) -> 22921.99 | M30: =IFERROR(SUM('Data Sheet'!H48:K48), 0) -> 22921.99
B31: Effective Tax Rate | C31: =C30/C27 -> 0.34532255 | D31: =D30/D27 -> 0.34791694 | E31: =E30/E27 -> 0.34595532 | F31: =F30/F27 -> 0.2853418 | G31: =G30/G27 -> 0.25561598 | H31: =H30/H27 -> 0.25008128 | I31: =I30/I27 -> 0.24959499 | J31: =J30/J27 -> 0.14525667 | ... L31: =L30/L27 -> 0.22441418 | M31: =IFERROR(M30/M27,0) -> 0
B33: Net Profit | C33: =IFERROR((C27-C30), 0) -> 15314.85 | D33: =IFERROR((D27-D30), 0) -> 18560.84 | E33: =IFERROR((E27-E30), 0) -> 22445.61 | F33: =IFERROR((F27-F30), 0) -> 27296.27 | G33: =IFERROR((G27-G30), 0) -> 31856.77 | H33: =IFERROR((H27-H30), 0) -> 38150.9 | I33: =IFERROR((I27-I30), 0) -> 46148.7 | J33: =IFERROR((J27-J30), 0) -> 65446.5 | ... M33: =IFERROR((M27-M30), 0) -> -22921.99
B34: Net Margins | C34: =C33/C6 -> 0.20901553 | D34: =D33/D6 -> 0.21762587 | E34: =E33/E6 -> 0.21344097 | F34: =F33/F6 -> 0.22339331 | G34: =G33/G6 -> 0.24781155 | H34: =H33/H6 -> 0.28065255 | I34: =I33/I6 -> 0.27026416 | J34: =J33/J6 -> 0.23073057 | ... M34: =M33/M6 -> -0.06575156
B36: No. of Equity Shares | C36: =IFERROR('Data Sheet'!B93, 0) -> 1025.02 | D36: =IFERROR('Data Sheet'!C93, 0) -> 1038.04 | E36: =IFERROR('Data Sheet'!D93, 0) -> 1089.32 | F36: =IFERROR('Data Sheet'!E93, 0) -> 1096.66 | G36: =IFERROR('Data Sheet'!F93, 0) -> 1102.56 | H36: =IFERROR('Data Sheet'!G93, 0) -> 1109.11 | I36: =IFERROR('Data Sheet'!H93, 0) -> 1115.95 | J36: =IFERROR('Data Sheet'!I93, 0) -> 1519.38 | ... L36: =IFERROR('Data Sheet'!K93, 0) -> 1539.34 | M36: -
B38: Earnings per Share | C38: =IFERROR(C33/C36, 0) -> 14.941026 | D38: =IFERROR(D33/D36, 0) -> 17.88066 | E38: =IFERROR(E33/E36, 0) -> 20.605157 | F38: =IFERROR(F33/F36, 0) -> 24.890367 | G38: =IFERROR(G33/G36, 0) -> 28.893457 | H38: =IFERROR(H33/H36, 0) -> 34.39776 | I38: =IFERROR(I33/I36, 0) -> 41.353734 | J38: =IFERROR(J33/J36, 0) -> 43.074478 | ... L38: =IFERROR(L33/L36, 0) -> 51.463263
B39: EPS Growth % | D39: =IFERROR(D38/C38-1,0) -> 0.19674916 | E39: =IFERROR(E38/D38-1,0) -> 0.1523712 | F39: =IFERROR(F38/E38-1,0) -> 0.20796783 | G39: =IFERROR(G38/F38-1,0) -> 0.16082888 | H39: =IFERROR(H38/G38-1,0) -> 0.19050345 | I39: =IFERROR(I38/H38-1,0) -> 0.20222172 | J39: =IFERROR(J38/I38-1,0) -> 0.041610347 | K39: =IFERROR(K38/J38-1,0) -> 0.11403118 | L39: =IFERROR(L38/K38-1,0) -> 0.072457171
B41: Dividend per Share | C41: =IFERROR('Data Sheet'!B31/'Data Sheet'!B93,0) -> 2.7499951 | D41: =IFERROR('Data Sheet'!C31/'Data Sheet'!C93,0) -> 3.25 | E41: =IFERROR('Data Sheet'!D31/'Data Sheet'!D93,0) -> 3.75 | F41: =IFERROR('Data Sheet'!E31/'Data Sheet'!E93,0) -> 1.2499954 | G41: =IFERROR('Data Sheet'!F31/'Data Sheet'!F93,0) -> 3.25 | H41: =IFERROR('Data Sheet'!G31/'Data Sheet'!G93,0) -> 7.7499256 | I41: =IFERROR('Data Sheet'!H31/'Data Sheet'!H93,0) -> 9.4999149 | J41: =IFERROR('Data Sheet'!I31/'Data Sheet'!I93,0) -> 9.7500033 | ... M41: =IFERROR('Data Sheet'!L31/'Data Sheet'!L93,0) -> 0
B42: Dividend payout ratio | C42: =IFERROR(C41/C38,0) -> 0.18405665 | D42: =IFERROR(D41/D38,0) -> 0.18176063 | E42: =IFERROR(E41/E38,0) -> 0.18199327 | F42: =IFERROR(F41/F38,0) -> 0.050220048 | G42: =IFERROR(G41/G38,0) -> 0.11248221 | H42: =IFERROR(H41/H38,0) -> 0.2253032 | I42: =IFERROR(I41/I38,0) -> 0.22972326 | J42: =IFERROR(J41/J38,0) -> 0.22635221 | ... L42: =IFERROR(L41/L38,0) -> 0.30118572
B44: Retained Earnings | C44: =IFERROR(IF(C38>C41, 1-C42),0) -> 0.81594335 | D44: =IFERROR(IF(D38>D41, 1-D42),0) -> 0.81823937 | E44: =IFERROR(IF(E38>E41, 1-E42),0) -> 0.81800673 | F44: =IFERROR(IF(F38>F41, 1-F42),0) -> 0.94977995 | G44: =IFERROR(IF(G38>G41, 1-G42),0) -> 0.88751779 | H44: =IFERROR(IF(H38>H41, 1-H42),0) -> 0.7746968 | I44: =IFERROR(IF(I38>I41, 1-I42),0) -> 0.77027674 | J44: =IFERROR(IF(J38>J41, 1-J42),0) -> 0.77364779 | ... L44: =IFERROR(IF(L38>L41, 1-L42),0) -> 0.69881428
A46: # | B46: Balance Sheet
B47: Equity Share Capital | C47: =IFERROR('Data Sheet'!B57,0) -> 512.51 | D47: =IFERROR('Data Sheet'!C57,0) -> 519.02 | E47: =IFERROR('Data Sheet'!D57,0) -> 544.66 | F47: =IFERROR('Data Sheet'!E57,0) -> 548.33 | G47: =IFERROR('Data Sheet'!F57,0) -> 551.28 | H47: =IFERROR('Data Sheet'!G57,0) -> 554.55 | I47: =IFERROR('Data Sheet'!H57,0) -> 557.97 | J47: =IFERROR('Data Sheet'!I57,0) -> 759.69 | ... L47: =IFERROR('Data Sheet'!K57,0) -> 1539.34
B48: Reserves | C48: =IFERROR('Data Sheet'!B58,0) -> 91281.44 | D48: =IFERROR('Data Sheet'!C58,0) -> 109080.11 | E48: =IFERROR('Data Sheet'!D58,0) -> 153128 | F48: =IFERROR('Data Sheet'!E58,0) -> 175810.38 | G48: =IFERROR('Data Sheet'!F58,0) -> 209258.9 | H48: =IFERROR('Data Sheet'!G58,0) -> 246771.62 | I48: =IFERROR('Data Sheet'!H58,0) -> 288879.53 | J48: =IFERROR('Data Sheet'!I58,0) -> 455635.56 | ... L48: =IFERROR('Data Sheet'!K58,0) -> 579975.02
B49: Borrowings | C49: =IFERROR('Data Sheet'!B59,0) -> 741549.89 | D49: =IFERROR('Data Sheet'!C59,0) -> 944817.22 | E49: =IFERROR('Data Sheet'!D59,0) -> 1080235.5 | F49: =IFERROR('Data Sheet'!E59,0) -> 1333041.4 | G49: =IFERROR('Data Sheet'!F59,0) -> 1511417.6 | H49: =IFERROR('Data Sheet'!G59,0) -> 1784969.5 | I49: =IFERROR('Data Sheet'!H59,0) -> 2139211.9 | J49: =IFERROR('Data Sheet'!I59,0) -> 3107502.7 | ... L49: =IFERROR('Data Sheet'!K59,0) -> 3688122.8
B50: Other Liabilities | C50: =IFERROR('Data Sheet'!B60,0) -> 59000.32 | D50: =IFERROR('Data Sheet'!C60,0) -> 48769.82 | E50: =IFERROR('Data Sheet'!D60,0) -> 58897.59 | F50: =IFERROR('Data Sheet'!E60,0) -> 71430.27 | G50: =IFERROR('Data Sheet'!F60,0) -> 78278.83 | H50: =IFERROR('Data Sheet'!G60,0) -> 90638.6 | I50: =IFERROR('Data Sheet'!H60,0) -> 101783.03 | J50: =IFERROR('Data Sheet'!I60,0) -> 466296.27 | ... L50: =IFERROR('Data Sheet'!K60,0) -> 638403.64
B51: Total Liabilities | C51: =IFERROR('Data Sheet'!B61,0) -> 892344.16 | D51: =IFERROR('Data Sheet'!C61,0) -> 1103186.2 | E51: =IFERROR('Data Sheet'!D61,0) -> 1292805.7 | F51: =IFERROR('Data Sheet'!E61,0) -> 1580830.4 | G51: =IFERROR('Data Sheet'!F61,0) -> 1799506.6 | H51: =IFERROR('Data Sheet'!G61,0) -> 2122934.3 | I51: =IFERROR('Data Sheet'!H61,0) -> 2530432.4 | J51: =IFERROR('Data Sheet'!I61,0) -> 4030194.3 | ... L51: =IFERROR('Data Sheet'!K61,0) -> 4908040.8
B53: Fixed Assets Net Block | C53: =IFERROR('Data Sheet'!B62,0) -> 3999.7 | D53: =IFERROR('Data Sheet'!C62,0) -> 4008.13 | E53: =IFERROR('Data Sheet'!D62,0) -> 4368.63 | F53: =IFERROR('Data Sheet'!E62,0) -> 4775.65 | G53: =IFERROR('Data Sheet'!F62,0) -> 5248.35 | H53: =IFERROR('Data Sheet'!G62,0) -> 6432.07 | I53: =IFERROR('Data Sheet'!H62,0) -> 8431.35 | J53: =IFERROR('Data Sheet'!I62,0) -> 12603.76 | ... L53: =IFERROR('Data Sheet'!K62,0) -> 16491.59
B54: Capital Work in Progress | C54: =IFERROR('Data Sheet'!B63,0) -> 0 | D54: =IFERROR('Data Sheet'!C63,0) -> 0 | E54: =IFERROR('Data Sheet'!D63,0) -> 0 | F54: =IFERROR('Data Sheet'!E63,0) -> 0 | G54: =IFERROR('Data Sheet'!F63,0) -> 0 | H54: =IFERROR('Data Sheet'!G63,0) -> 0 | I54: =IFERROR('Data Sheet'!H63,0) -> 0 | J54: =IFERROR('Data Sheet'!I63,0) -> 0 | ... L54: =IFERROR('Data Sheet'!K63,0) -> 0
B55: Investments | C55: =IFERROR('Data Sheet'!B64,0) -> 210777.11 | D55: =IFERROR('Data Sheet'!C64,0) -> 238460.92 | E55: =IFERROR('Data Sheet'!D64,0) -> 289445.87 | F55: =IFERROR('Data Sheet'!E64,0) -> 389304.95 | G55: =IFERROR('Data Sheet'!F64,0) -> 438823.11 | H55: =IFERROR('Data Sheet'!G64,0) -> 449263.86 | I55: =IFERROR('Data Sheet'!H64,0) -> 511581.71 | J55: =IFERROR('Data Sheet'!I64,0) -> 1005681.6 | ... L55: =IFERROR('Data Sheet'!K64,0) -> 1280216.3
B56: Other Assets | C56: =IFERROR('Data Sheet'!B65-1*(SUM(HistoricalFS!C59:C61)),0) -> 643934.07 | D56: =IFERROR('Data Sheet'!C65-1*(SUM(HistoricalFS!D59:D61)),0) -> 763578.98 | E56: =IFERROR('Data Sheet'!D65-1*(SUM(HistoricalFS!E59:E61)),0) -> 959619.08 | F56: =IFERROR('Data Sheet'!E65-1*(SUM(HistoricalFS!F59:F61)),0) -> 1123752.4 | G56: =IFERROR('Data Sheet'!F65-1*(SUM(HistoricalFS!G59:G61)),0) -> 1268787 | H56: =IFERROR('Data Sheet'!G65-1*(SUM(HistoricalFS!H59:H61)),0) -> 1548447.2 | I56: =IFERROR('Data Sheet'!H65-1*(SUM(HistoricalFS!I59:I61)),0) -> 1906501.4 | J56: =IFERROR('Data Sheet'!I65-1*(SUM(HistoricalFS!J59:J61)),0) -> 2846250.3 | ... L56: =IFERROR('Data Sheet'!K65-1*(SUM(HistoricalFS!L59:L61)),0) -> 3410625.9
B57: Total Non Current Assets | C57: =IFERROR(SUM(C53:C56),0) -> 858710.88 | D57: =IFERROR(SUM(D53:D56),0) -> 1006048 | E57: =IFERROR(SUM(E53:E56),0) -> 1253433.6 | F57: =IFERROR(SUM(F53:F56),0) -> 1517833 | G57: =IFERROR(SUM(G53:G56),0) -> 1712858.5 | H57: =IFERROR(SUM(H53:H56),0) -> 2004143.1 | I57: =IFERROR(SUM(I53:I56),0) -> 2426514.5 | J57: =IFERROR(SUM(J53:J56),0) -> 3864535.7 | ... L57: =IFERROR(SUM(L53:L56),0) -> 4707333.7
...

Sheet Ratio Analysis
B2: ="Ratio Analysis"&" - "&'Data Sheet'!B1 -> Ratio Analysis - HDFC BANK LTD
B3: Years | C3: =HistoricalFS!C3 -> 42825 | D3: =HistoricalFS!D3 -> 43190 | E3: =HistoricalFS!E3 -> 43555 | F3: =HistoricalFS!F3 -> 43921 | G3: =HistoricalFS!G3 -> 44286 | H3: =HistoricalFS!H3 -> 44651 | I3: =HistoricalFS!I3 -> 45016 | J3: =HistoricalFS!J3 -> 45382 | ... L3: =HistoricalFS!L3 -> 46112 | M3: Trendline | N3: Mean | O3: Median
B5: PAT Growth | D5: =HistoricalFS!D33/HistoricalFS!C33-1 -> 0.21195049 | E5: =HistoricalFS!E33/HistoricalFS!D33-1 -> 0.20929926 | F5: =HistoricalFS!F33/HistoricalFS!E33-1 -> 0.21610729 | G5: =HistoricalFS!G33/HistoricalFS!F33-1 -> 0.16707411 | H5: =HistoricalFS!H33/HistoricalFS!G33-1 -> 0.1975759 | I5: =HistoricalFS!I33/HistoricalFS!H33-1 -> 0.20963595 | J5: =HistoricalFS!J33/HistoricalFS!I33-1 -> 0.41816563 | K5: =HistoricalFS!K33/HistoricalFS!J33-1 -> 0.12214053 | L5: =HistoricalFS!L33/HistoricalFS!K33-1 -> 0.078693854 | N5: =AVERAGE(D5:L5) -> 0.20340478 | O5: =MEDIAN(D5:L5) -> 0.20929926
B6: Book Value Growth | D6: =(SUM(HistoricalFS!D47:D48))/(SUM(HistoricalFS!C47:C48))-1 -> 0.19396899 | E6: =(SUM(HistoricalFS!E47:E48))/(SUM(HistoricalFS!D47:D48))-1 -> 0.40213394 | F6: =(SUM(HistoricalFS!F47:F48))/(SUM(HistoricalFS!E47:E48))-1 -> 0.1476258 | G6: =(SUM(HistoricalFS!G47:G48))/(SUM(HistoricalFS!F47:F48))-1 -> 0.18967858 | H6: =(SUM(HistoricalFS!H47:H48))/(SUM(HistoricalFS!G47:G48))-1 -> 0.1788092 | I6: =(SUM(HistoricalFS!I47:I48))/(SUM(HistoricalFS!H47:H48))-1 -> 0.17026637 | J6: =(SUM(HistoricalFS!J47:J48))/(SUM(HistoricalFS!I47:I48))-1 -> 0.57683524 | K6: =(SUM(HistoricalFS!K47:K48))/(SUM(HistoricalFS!J47:J48))-1 -> 0.14328401 | L6: =(SUM(HistoricalFS!L47:L48))/(SUM(HistoricalFS!K47:K48))-1 -> 0.11446183 | N6: =AVERAGE(D6:L6) -> 0.23522933 | O6: =MEDIAN(D6:L6) -> 0.1788092
B7: Dividend Growth | D7: =HistoricalFS!D41/HistoricalFS!C41-1 -> 0.18182028 | E7: =HistoricalFS!E41/HistoricalFS!D41-1 -> 0.15384615 | F7: =HistoricalFS!F41/HistoricalFS!E41-1 -> -0.66666788 | G7: =HistoricalFS!G41/HistoricalFS!F41-1 -> 1.6000095 | H7: =HistoricalFS!H41/HistoricalFS!G41-1 -> 1.3845925 | I7: =HistoricalFS!I41/HistoricalFS!H41-1 -> 0.22580723 | J7: =HistoricalFS!J41/HistoricalFS!I41-1 -> 0.026325333 | K7: =HistoricalFS!K41/HistoricalFS!J41-1 -> 0.12820475 | L7: =HistoricalFS!L41/HistoricalFS!K41-1 -> 0.40909091 | N7: =AVERAGE(D7:L7) -> 0.38255875 | O7: =MEDIAN(D7:L7) -> 0.18182028
B9: Return on Equity% | C9: =HistoricalFS!C33/(SUM(HistoricalFS!C47:C48)) -> 0.16683943 | D9: =HistoricalFS!D33/(SUM(HistoricalFS!D47:D48)) -> 0.16935207 | E9: =HistoricalFS!E33/(SUM(HistoricalFS!E47:E48)) -> 0.14606118 | F9: =HistoricalFS!F33/(SUM(HistoricalFS!F47:F48)) -> 0.15477699 | G9: =HistoricalFS!G33/(SUM(HistoricalFS!G47:G48)) -> 0.15183615 | H9: =HistoricalFS!H33/(SUM(HistoricalFS!H47:H48)) -> 0.15425339 | I9: =HistoricalFS!I33/(SUM(HistoricalFS!I47:I48)) -> 0.15944271 | J9: =HistoricalFS!J33/(SUM(HistoricalFS!J47:J48)) -> 0.14339873 | ... L9: =HistoricalFS!L33/(SUM(HistoricalFS!L47:L48)) -> 0.13622959 | N9: =AVERAGE(D9:L9) -> 0.15067751 | O9: =MEDIAN(D9:L9) -> 0.15183615
B10: Return on Assets% | C10: =HistoricalFS!C33/HistoricalFS!C64 -> 0.017162493 | D10: =HistoricalFS!D33/HistoricalFS!D64 -> 0.016824758 | E10: =HistoricalFS!E33/HistoricalFS!E64 -> 0.017361936 | F10: =HistoricalFS!F33/HistoricalFS!F64 -> 0.017267045 | G10: =HistoricalFS!G33/HistoricalFS!G64 -> 0.017703058 | H10: =HistoricalFS!H33/HistoricalFS!H64 -> 0.017970834 | I10: =HistoricalFS!I33/HistoricalFS!I64 -> 0.018237476 | J10: =HistoricalFS!J33/HistoricalFS!J64 -> 0.016239044 | ... L10: =HistoricalFS!L33/HistoricalFS!L64 -> 0.01614075 | N10: =AVERAGE(D10:L10) -> 0.01716287 | O10: =MEDIAN(D10:L10) -> 0.017267045
B12: Dividend Payout Ratio | C12: =HistoricalFS!C42 -> 0.18405665 | D12: =HistoricalFS!D42 -> 0.18176063 | E12: =HistoricalFS!E42 -> 0.18199327 | F12: =HistoricalFS!F42 -> 0.050220048 | G12: =HistoricalFS!G42 -> 0.11248221 | H12: =HistoricalFS!H42 -> 0.2253032 | I12: =HistoricalFS!I42 -> 0.22972326 | J12: =HistoricalFS!J42 -> 0.22635221 | ... L12: =HistoricalFS!L42 -> 0.30118572 | N12: =AVERAGE(D12:L12) -> 0.19313918 | O12: =MEDIAN(D12:L12) -> 0.2253032
B13: Retention Ratio | C13: =1-C12 -> 0.81594335 | D13: =1-D12 -> 0.81823937 | E13: =1-E12 -> 0.81800673 | F13: =1-F12 -> 0.94977995 | G13: =1-G12 -> 0.88751779 | H13: =1-H12 -> 0.7746968 | I13: =1-I12 -> 0.77027674 | J13: =1-J12 -> 0.77364779 | ... L13: =1-L12 -> 0.69881428 | N13: =AVERAGE(D13:L13) -> 0.80686082 | O13: =MEDIAN(D13:L13) -> 0.7746968
B14: Sustainable Growth Rate | C14: =C9*C13 -> 0.13613152 | D14: =D9*D13 -> 0.13857053 | E14: =E9*E13 -> 0.11947903 | F14: =F9*F13 -> 0.14700408 | G14: =G9*G13 -> 0.13475728 | H14: =H9*H13 -> 0.11949961 | I14: =I9*I13 -> 0.12281501 | J14: =J9*J13 -> 0.11094011 | ... L14: =L9*L13 -> 0.09519918 | N14: =AVERAGE(D14:L14) -> 0.12186088 | O14: =MEDIAN(D14:L14) -> 0.11949961

Sheet Raw FS
B2: Particulars | C2: 41699 | D2: 42064 | E2: 42430 | F2: 42795 | G2: 43160 | H2: 43525 | I2: 43891 | J2: 44256 | K2: 44621 | L2: 44986 | M2: 45352 | N2: 45717
B4: Reserves | C4: 3943 | D4: 4646 | E4: 6429 | F4: 7508 | G4: 8314 | H4: 9375 | I4: 10034 | J4: 12710 | K4: 13716 | L4: 15896 | M4: 18632 | N4: 19304
B5: Borrowings -
B6: Long term Borrowings | C6: 41 | D6: 78 | E6: 73 | F6: 41 | G6: 28 | H6: 19 | I6: 19 | J6: 15 | K6: 45 | L6: 76 | M6: 54 | N6: 260
B7: Short term Borrowings | C7: 199 | D7: 332 | E7: 231 | F7: 504 | G7: 492 | H7: 597 | I7: 321 | J7: 326 | K7: 731 | L7: 896 | M7: 1053 | N7: 604
B8: Lease Liabilities | C8: 0 | D8: 0 | E8: 0 | F8: 0 | G8: 0 | H8: 693 | I8: 764 | J8: 745 | K8: 811 | L8: 960 | M8: 1367 | N8: 1427
B9: Other Borrowings | C9: 9 | D9: 8 | E9: 20 | F9: 15 | G9: 13 | H9: 11 | I9: 15 | J9: 8 | K9: 0 | L9: 0 | M9: 0 | N9: 0
B10: Other Liabilities -
B11: Non controlling int | C11: 246 | D11: 264 | E11: 384 | F11: 375 | G11: 328 | H11: 361 | I11: 404 | J11: 423 | K11: 388 | L11: 454 | M11: 695 | N11: 659
B12: Trade Payables | C12: 1746 | D12: 1549 | E12: 1565 | F12: 1923 | G12: 2160 | H12: 2394 | I12: 2137 | J12: 3379 | K12: 4164 | L12: 3635 | M12: 3831 | N12: 3848
B13: Advance from Customers | C13: 0 | D13: 5 | E13: 12 | F13: 17 | G13: 16 | H13: 13 | I13: 29 | J13: 41 | K13: 76 | L13: 108 | M13: 154 | N13: 173
B14: Other liability items | C14: 1795 | D14: 1937 | E14: 1750 | F14: 1925 | G14: 2316 | H14: 2690 | I14: 2320 | J14: 2613 | K14: 2932 | L14: 3657 | M14: 4017 | N14: 3985
B15: Total Liabilities | C15: 8075 | D15: 8914 | E15: 10559 | F15: 12405 | G15: 13763 | H15: 16249 | I15: 16138 | J15: 20355 | K15: 22958 | L15: 25779 | M15: 29901 | N15: 30355
B17: Fixed Assets -
B18: Land | C18: 247 | D18: 251 | E18: 429 | F18: 408 | G18: 586 | H18: 605 | I18: 644 | J18: 644 | K18: 644 | L18: 804 | M18: 1126 | N18: 1050
B19: Building | C19: 931 | D19: 962 | E19: 923 | F19: 931 | G19: 957 | H19: 2402 | I19: 2460 | J19: 2249 | K19: 2325 | L19: 2883 | M19: 3390 | N19: 4136
B20: Plant Machinery | C20: 2054 | D20: 2132 | E20: 1793 | F20: 1980 | G20: 2157 | H20: 4006 | I20: 4208 | J20: 4340 | K20: 4531 | L20: 4825 | M20: 5422 | N20: 7576
B21: Equipments | C21: 155 | D21: 171 | E21: 97 | F21: 119 | G21: 200 | H21: 221 | I21: 241 | J21: 243 | K21: 253 | L21: 270 | M21: 298 | N21: 325
B22: Furniture n fittings | C22: 71 | D22: 83 | E22: 49 | F22: 59 | G22: 72 | H22: 88 | I22: 94 | J22: 99 | K22: 113 | L22: 146 | M22: 175 | N22: 203
B23: Vehicles | C23: 14 | D23: 18 | E23: 11 | F23: 14 | G23: 27 | H23: 47 | I23: 50 | J23: 38 | K23: 32 | L23: 36 | M23: 40 | N23: 39
B24: Intangible Assets | C24: 203 | D24: 351 | E24: 339 | F24: 276 | G24: 468 | H24: 512 | I24: 505 | J24: 476 | K24: 345 | L24: 422 | M24: 850 | N24: 827
B25: Other fixed assets | C25: 128 | D25: 145 | E25: 103 | F25: 128 | G25: 238 | H25: 261 | I25: 293 | J25: 302 | K25: 294 | L25: 289 | M25: 321 | N25: 328
B26: Gross Block | C26: 3804 | D26: 4112 | E26: 3744 | F26: 3914 | G26: 4705 | H26: 8141 | I26: 8495 | J26: 8392 | K26: 8538 | L26: 9676 | M26: 11622 | N26: 14484
B27: Accumulated Depreciation | C27: 1242 | D27: 1452 | E27: 327 | F27: 610 | G27: 973 | H27: 1644 | I27: 2223 | J27: 2533 | K27: 3019 | L27: 3905 | M27: 4475 | N27: 5264
B28: Net Block | C28: =SUM(C26:C27) -> 5046 | D28: =SUM(D26:D27) -> 5564 | E28: =SUM(E26:E27) -> 4071 | F28: =SUM(F26:F27) -> 4524 | G28: =SUM(G26:G27) -> 5678 | H28: =SUM(H26:H27) -> 9785 | I28: =SUM(I26:I27) -> 10718 | J28: =SUM(J26:J27) -> 10925 | ... N28: =SUM(N26:N27) -> 19748
B30: CWIP | C30: 72 | D30: 196 | E30: 107 | F30: 258 | G30: 1405 | H30: 210 | I30: 140 | J30: 183 | K30: 426 | L30: 1020 | M30: 2698 | N30: 1254
B31: Investments | C31: 1424 | D31: 1588 | E31: 2712 | F31: 2652 | G31: 2141 | H31: 2569 | I31: 2019 | J31: 4737 | K31: 3248 | L31: 4262 | M31: 4588 | N31: 4725
B32: Other Assets -
B33: Inventories | C33: 2070 | D33: 2259 | E33: 1998 | F33: 2627 | G33: 2658 | H33: 3150 | I33: 3390 | J33: 3799 | K33: 6153 | L33: 6211 | M33: 5923 | N33: 6719
B34: Trade receivables + | C34: 1110 | D34: 1182 | E34: 1187 | F34: 1447 | G34: 1731 | H34: 1907 | I34: 1795 | J34: 2602 | K34: 3871 | L34: 4637 | M34: 4889 | N34: 4314
B35: Cash Equivalents | C35: 229 | D35: 204 | E35: 424 | F35: 801 | G35: 405 | H35: 445 | I35: 783 | J35: 611 | K35: 864 | L35: 844 | M35: 1084 | N35: 782
B36: Loans n Advances | C36: 7 | D36: 8 | E36: 9 | F36: 14 | G36: 13 | H36: 16 | I36: 12 | J36: 12 | K36: 8 | L36: 12 | M36: 17 | N36: 22
B37: Other asset items | C37: 603 | D37: 817 | E37: 705 | F37: 1303 | G37: 1678 | H37: 1456 | I37: 1727 | J37: 2554 | K37: 2869 | L37: 3024 | M37: 3555 | N37: 3319
B38: Total Assets | C38: 8075 | D38: 8914 | E38: 10559 | F38: 12405 | G38: 13763 | H38: 16249 | I38: 16138 | J38: 20355 | K38: 22958 | L38: 25779 | M38: 29901 | N38: 30355
C40: 41699 | D40: 42064 | E40: 42430 | F40: 42795 | G40: 43160 | H40: 43525 | I40: 43891 | J40: 44256 | K40: 44621 | L40: 44986 | M40: 45352 | N40: 45717
B41: Cash from Operating Activity - | C41: 1402 | D41: 1188 | E41: 2243 | F41: 1527 | G41: 2113 | H41: 2470 | I41: 2632 | J41: 3683 | K41: 986 | L41: 4193 | M41: 6104 | N41: 4424
B42: Profit from operations | C42: 2051 | D42: 2271 | E42: 2848 | F42: 3056 | G42: 3274 | H42: 3861 | I42: 4380 | J42: 4970 | K42: 4957 | L42: 6460 | M42: 7929 | N42: 6390
B43: Receivables | C43: -254 | D43: -155 | E43: -146 | F43: -475 | G43: -483 | H43: -205 | I43: 160 | J43: -1342 | K43: -1326 | L43: -834 | M43: -362 | N43: 282
B44: Inventory | C44: -231 | D44: -144 | E44: 202 | F44: -629 | G44: -39 | H44: -492 | I44: -251 | J44: -409 | K44: -2354 | L44: -56 | M44: 315 | N44: -805
B45: Payables | C45: 317 | D45: -151 | E45: 142 | F45: 501 | G45: 442 | H45: 287 | I45: -647 | J45: 1544 | K45: 644 | L45: -539 | M45: 269 | N45: -160
...

Sheet Data Room>
B2: Date
C3: Adj Close | E3: Date
B4: 44378 | C4: 678.47 | F4: Adj Close
B5: 44409 | C5: 752.17 | E5: 44378 | F5: 15763.05
B6: 44440 | C6: 758.62 | E6: 44409 | F6: 17132.2
B7: 44470 | C7: 752.86 | E7: 44440 | F7: 17618.15
B8: 44501 | C8: 710.39 | E8: 44470 | F8: 17671.65
B9: 44531 | C9: 703.66 | E9: 44501 | F9: 16983.2
B10: 44562 | C10: 706.65 | E10: 44531 | F10: 17354.05
B11: 44593 | C11: 678.38 | E11: 44562 | F11: 17339.85
B12: 44621 | C12: 699.35 | E12: 44593 | F12: 16793.9
B13: 44652 | C13: 658.57 | E13: 44621 | F13: 17464.75
B14: 44682 | C14: 660.64 | E14: 44652 | F14: 17102.55
B15: 44713 | C15: 648.61 | E15: 44682 | F15: 16584.55
B16: 44743 | C16: 690.09 | E16: 44713 | F16: 15780.25
... B64: 46183 | C64: 746.85 | E64: 46174 | F64: 23123
E65: 46183 | F65: 23214.95

Sheet Beta-Regression
B2: Regression Beta - 5 Yrs Monthly
B4: HDFC Monthly Returns | F4: NIFTY 50 Monthly Returns | J4: Beta Drifting | N4: Beta | O4: =K33 -> 0.95394139
B6: Closing Date | C6: Adj Close | D6: Returns | F6: Closing Date | G6: Adj Close | H6: Returns | J6: Levered Raw Beta | L6: =O4 -> 0.95394139
B7: 44378 | C7: 678.47 | F7: 44378 | G7: 15763.05 | J7: Raw Beta Weight | L7: 0.75
B8: 44409 | C8: 752.17 | D8: =C8/C7-1 -> 0.10862676 | F8: 44409 | G8: 17132.2 | H8: =G8/G7-1 -> 0.086858191
B9: 44440 | C9: 758.62 | D9: =C9/C8-1 -> 0.0085751891 | F9: 44440 | G9: 17618.15 | H9: =G9/G8-1 -> 0.028364717 | J9: Market Beta | L9: 1
B10: 44470 | C10: 752.86 | D10: =C10/C9-1 -> -0.0075927342 | F10: 44470 | G10: 17671.65 | H10: =G10/G9-1 -> 0.0030366412 | J10: Market Beta weight | L10: 0.25
B11: 44501 | C11: 710.39 | D11: =C11/C10-1 -> -0.056411551 | F11: 44501 | G11: 16983.2 | H11: =G11/G10-1 -> -0.038957879
B12: 44531 | C12: 703.66 | D12: =C12/C11-1 -> -0.0094736694 | F12: 44531 | G12: 17354.05 | H12: =G12/G11-1 -> 0.021836285 | J12: Adjusted Beta | L12: =(L6*L7)+(L9*L10) -> 0.96545604
B13: 44562 | C13: 706.65 | D13: =C13/C12-1 -> 0.0042492113 | F13: 44562 | G13: 17339.85 | H13: =G13/G12-1 -> -0.0008182528
B14: 44593 | C14: 678.38 | D14: =C14/C13-1 -> -0.040005661 | F14: 44593 | G14: 16793.9 | H14: =G14/G13-1 -> -0.031485278
B15: 44621 | C15: 699.35 | D15: =C15/C14-1 -> 0.030911878 | F15: 44621 | G15: 17464.75 | H15: =G15/G14-1 -> 0.039946052
B16: 44652 | C16: 658.57 | D16: =C16/C15-1 -> -0.058311289 | F16: 44652 | G16: 17102.55 | H16: =G16/G15-1 -> -0.020738917 | J16: SUMMARY OUTPUT
B17: 44682 | C17: 660.64 | D17: =C17/C16-1 -> 0.0031431738 | F17: 44682 | G17: 16584.55 | H17: =G17/G16-1 -> -0.030287881
B18: 44713 | C18: 648.61 | D18: =C18/C17-1 -> -0.018209615 | F18: 44713 | G18: 15780.25 | H18: =G18/G17-1 -> -0.048496944 | J18: Regression Statistics
B19: 44743 | C19: 690.09 | D19: =C19/C18-1 -> 0.063952144 | F19: 44743 | G19: 17158.25 | H19: =G19/G18-1 -> 0.087324345 | J19: Multiple R | K19: 0.70824212
B20: 44774 | C20: 715.06 | D20: =C20/C19-1 -> 0.036183686 | F20: 44774 | G20: 17759.3 | H20: =G20/G19-1 -> 0.035029796 | J20: R Square | K20: 0.50160691
B21: 44805 | C21: 683.91 | D21: =C21/C20-1 -> -0.043562778 | F21: 44805 | G21: 17094.35 | H21: =G21/G20-1 -> -0.037442354 | J21: Adjusted R Square | K21: 0.49301392
B22: 44835 | C22: 720.16 | D22: =C22/C21-1 -> 0.05300405 | F22: 44835 | G22: 18012.2 | H22: =G22/G21-1 -> 0.053693179 | J22: Standard Error | K22: 0.037669569
